Workbook

Sheet Start Here
A1: Zava Supply Co. - FY2026 Forecast Pack - Q3 Update (9+3)
A2: Workshop file for 'Copilot for Finance Controllers'. Compare the prior (Q2, 6+6) forecast with the current (Q3, 9+3) forecast and tell the story.
A3: TRAINING DATA ONLY - Zava Supply Co. is a fictitious company. All names and numbers are invented for the Copilot Finance Controllers workshop.
A5: Sheet | B5: What it contains / how you will use it
A6: Overview | B6: Full-year 2026 by business unit: Budget, Prior FCAST (Q2 6+6, as reported), Operational Adjustments, Current FCAST (Q3 9+3), and changes.
A7: Forecast | B7: Current forecast by month: January-September actuals plus October-December forecast, for Sales, Gross Margin, Op Costs, PBITA, ratios and Sales/Day.
A8: Adjustments | B8: Every operational adjustment that moves the prior forecast to the current forecast, with business unit, driver category, months affected, and Sales / Gross Margin / Op Costs / PBITA impact.
A9: Variances | B9: Your working template to draft forecast-change commentary for Sales, Gross Margin, Op Costs and PBITA.
A10: R&Os | B10: Risks and opportunities NOT yet included in the current forecast, with probability and weighted PBITA impact.
A11: Billing Days | B11: Billing days and daily sales by month (actuals Jan-Sep, forecast Oct-Dec).
A13: Data notes
A14: • | B14: All amounts are in USD thousands ($000s) unless labeled otherwise.
A15: • | B15: Op Costs = Warehouse & Delivery + Selling + G&A. PBITA = Gross Margin - Op Costs.
A16: • | B16: Sign convention: costs are shown as positive numbers. For Sales, Gross Margin and PBITA a positive variance is FAVORABLE; for Cost of Sales and Op Costs a positive variance is UNFAVORABLE. Tell Copilot this when you ask about favorable/unfavorable items.
A17: • | B17: Budget was built as prior year + growth (sales +4%), so 'actual vs prior year' is a reasonable proxy for budget drivers at customer level. There is no customer-level budget.
A18: • | B18: Business units: Foodservice Packaging, Janitorial & Sanitation, Safety & PPE, Retail Supplies. 'Consolidated' = sum of the four.
A19: • | B19: Tip: make a copy of this workbook before you start (File > Save a copy) so you can always return to the original. Ctrl+Z undoes Copilot edits.
A20: • | B20: Prior FCAST + Operational Adjustments = Current FCAST. The 'Tie-out check' column on Overview should be zero.
A21: • | B21: One adjustment (duplicate July utilities accrual) has no full-year impact because it reverses in October - it is a timing item.

Sheet Overview
A1: FY2026 Forecast Overview - Prior FCAST vs Current FCAST vs Budget
A2: USD $000s | Full Year 2026 | Prior FCAST = Q2 (6+6) as reported; Current FCAST = Q3 (9+3)
A3: TRAINING DATA ONLY - Zava Supply Co. is a fictitious company. All names and numbers are invented for the Copilot Finance Controllers workshop.
A5: Business Unit | B5: Metric | C5: Budget FY26 | D5: Prior FCAST (Q2 6+6) | E5: Operational Adjustments | F5: Current FCAST (Q3 9+3) | G5: Change vs Prior FCAST % | H5: Current FCAST vs Budget $ | I5: Current FCAST vs Budget % | J5: Tie-out check (should be 0)
A6: Consolidated | B6: Sales | C6: =C13+C20+C27+C34 -> 493192.4 | D6: =D13+D20+D27+D34 -> 478399.8 | E6: =SUM(Adjustments!F6:F27) -> 8120.6 | F6: =D6+E6 -> 486520.4 | G6: =IFERROR((F6-D6)/ABS(D6),0) -> 0.016974505 | H6: =F6-C6 -> -6672 | I6: =IFERROR((F6-C6)/ABS(C6),0) -> -0.013528189 | J6: =ROUND(F6-Forecast!O7,1) -> 0
A7: Consolidated | B7: Gross Margin | C7: =C14+C21+C28+C35 -> 131433.6 | D7: =D14+D21+D28+D35 -> 126633.7 | E7: =SUM(Adjustments!G6:G27) -> 484.6 | F7: =D7+E7 -> 127118.3 | G7: =IFERROR((F7-D7)/ABS(D7),0) -> 0.0038267854 | H7: =F7-C7 -> -4315.3 | I7: =IFERROR((F7-C7)/ABS(C7),0) -> -0.032832548 | J7: =ROUND(F7-Forecast!O8,1) -> 0
A8: Consolidated | B8: Op Costs | C8: =C15+C22+C29+C36 -> 94944.4 | D8: =D15+D22+D29+D36 -> 92865.4 | E8: =SUM(Adjustments!H6:H27) -> 3798.3 | F8: =D8+E8 -> 96663.7 | G8: =IFERROR((F8-D8)/ABS(D8),0) -> 0.040901132 | H8: =F8-C8 -> 1719.3 | I8: =IFERROR((F8-C8)/ABS(C8),0) -> 0.018108493 | J8: =ROUND(F8-Forecast!O10,1) -> 0
A9: Consolidated | B9: PBITA | C9: =C7-C8 -> 36489.2 | D9: =D7-D8 -> 33768.3 | E9: =E7-E8 -> -3313.7 | F9: =F7-F8 -> 30454.6 | G9: =IFERROR((F9-D9)/ABS(D9),0) -> -0.098130495 | H9: =F9-C9 -> -6034.6 | I9: =IFERROR((F9-C9)/ABS(C9),0) -> -0.16538044 | J9: =ROUND(F9-Forecast!O12,1) -> 0
A10: Consolidated | B10: GM % | C10: =IFERROR(C7/C6,0) -> 0.26649559 | D10: =IFERROR(D7/D6,0) -> 0.26470266 | F10: =IFERROR(F7/F6,0) -> 0.26128051 | G10: =(F10-D10)*100 -> -0.34221472 | H10: =(F10-C10)*100 -> -0.52150771
A11: Consolidated | B11: Op Cost % | C11: =IFERROR(C8/C6,0) -> 0.19250986 | D11: =IFERROR(D8/D6,0) -> 0.19411672 | F11: =IFERROR(F8/F6,0) -> 0.19868376 | G11: =(F11-D11)*100 -> 0.45670351 | H11: =(F11-C11)*100 -> 0.61738948
A12: Consolidated | B12: PBITA % | C12: =IFERROR(C9/C6,0) -> 0.073985731 | D12: =IFERROR(D9/D6,0) -> 0.070585941 | F12: =IFERROR(F9/F6,0) -> 0.062596759 | G12: =(F12-D12)*100 -> -0.79891823 | H12: =(F12-C12)*100 -> -1.1388972
A13: Foodservice Packaging | B13: Sales | C13: 176550.8 | D13: 174753.3 | E13: =SUMIFS(Adjustments!F6:F27,Adjustments!B6:B27,A13) -> 10547.4 | F13: =D13+E13 -> 185300.7 | G13: =IFERROR((F13-D13)/ABS(D13),0) -> 0.060355942 | H13: =F13-C13 -> 8749.9 | I13: =IFERROR((F13-C13)/ABS(C13),0) -> 0.04956024 | J13: =ROUND(F13-Forecast!O15,1) -> 0
A14: Foodservice Packaging | B14: Gross Margin | C14: 43254.9 | D14: 42842.5 | E14: =SUMIFS(Adjustments!G6:G27,Adjustments!B6:B27,A14) -> 2240.7 | F14: =D14+E14 -> 45083.2 | G14: =IFERROR((F14-D14)/ABS(D14),0) -> 0.052300869 | H14: =F14-C14 -> 1828.3 | I14: =IFERROR((F14-C14)/ABS(C14),0) -> 0.042268044 | J14: =ROUND(F14-Forecast!O16,1) -> 0
A15: Foodservice Packaging | B15: Op Costs | C15: 33533.7 | D15: 33139.5 | E15: =SUMIFS(Adjustments!H6:H27,Adjustments!B6:B27,A15) -> 2902.1 | F15: =D15+E15 -> 36041.6 | G15: =IFERROR((F15-D15)/ABS(D15),0) -> 0.087572233 | H15: =F15-C15 -> 2507.9 | I15: =IFERROR((F15-C15)/ABS(C15),0) -> 0.074787453 | J15: =ROUND(F15-Forecast!O18,1) -> 0
A16: Foodservice Packaging | B16: PBITA | C16: =C14-C15 -> 9721.2 | D16: =D14-D15 -> 9703 | E16: =E14-E15 -> -661.4 | F16: =F14-F15 -> 9041.6 | G16: =IFERROR((F16-D16)/ABS(D16),0) -> -0.068164485 | H16: =F16-C16 -> -679.6 | I16: =IFERROR((F16-C16)/ABS(C16),0) -> -0.069909065 | J16: =ROUND(F16-Forecast!O20,1) -> 0
A17: Foodservice Packaging | B17: GM % | C17: =IFERROR(C14/C13,0) -> 0.24499974 | D17: =IFERROR(D14/D13,0) -> 0.24515989 | F17: =IFERROR(F14/F13,0) -> 0.24329752 | G17: =(F17-D17)*100 -> -0.18623752 | H17: =(F17-C17)*100 -> -0.17022236
A18: Foodservice Packaging | B18: Op Cost % | C18: =IFERROR(C15/C13,0) -> 0.18993797 | D18: =IFERROR(D15/D13,0) -> 0.1896359 | F18: =IFERROR(F15/F13,0) -> 0.19450331 | G18: =(F18-D18)*100 -> 0.48674089 | H18: =(F18-C18)*100 -> 0.45653459
A19: Foodservice Packaging | B19: PBITA % | C19: =IFERROR(C16/C13,0) -> 0.055061773 | D19: =IFERROR(D16/D13,0) -> 0.055523987 | F19: =IFERROR(F16/F13,0) -> 0.048794203 | G19: =(F19-D19)*100 -> -0.67297841 | H19: =(F19-C19)*100 -> -0.62675694
A20: Janitorial & Sanitation | B20: Sales | C20: 121804.4 | D20: 118103.9 | E20: =SUMIFS(Adjustments!F6:F27,Adjustments!B6:B27,A20) -> -310.4 | F20: =D20+E20 -> 117793.5 | G20: =IFERROR((F20-D20)/ABS(D20),0) -> -0.0026281943 | H20: =F20-C20 -> -4010.9 | I20: =IFERROR((F20-C20)/ABS(C20),0) -> -0.032929024 | J20: =ROUND(F20-Forecast!O23,1) -> 0
A21: Janitorial & Sanitation | B21: Gross Margin | C21: 34592.5 | D21: 33620.2 | E21: =SUMIFS(Adjustments!G6:G27,Adjustments!B6:B27,A21) -> 161.7 | F21: =D21+E21 -> 33781.9 | G21: =IFERROR((F21-D21)/ABS(D21),0) -> 0.0048096085 | H21: =F21-C21 -> -810.6 | I21: =IFERROR((F21-C21)/ABS(C21),0) -> -0.023432825 | J21: =ROUND(F21-Forecast!O24,1) -> 0
A22: Janitorial & Sanitation | B22: Op Costs | C22: 23529.9 | D22: 23051.2 | E22: =SUMIFS(Adjustments!H6:H27,Adjustments!B6:B27,A22) -> 333.4 | F22: =D22+E22 -> 23384.6 | G22: =IFERROR((F22-D22)/ABS(D22),0) -> 0.014463455 | H22: =F22-C22 -> -145.3 | I22: =IFERROR((F22-C22)/ABS(C22),0) -> -0.0061751219 | J22: =ROUND(F22-Forecast!O26,1) -> 0
A23: Janitorial & Sanitation | B23: PBITA | C23: =C21-C22 -> 11062.6 | D23: =D21-D22 -> 10569 | E23: =E21-E22 -> -171.7 | F23: =F21-F22 -> 10397.3 | G23: =IFERROR((F23-D23)/ABS(D23),0) -> -0.016245624 | H23: =F23-C23 -> -665.3 | I23: =IFERROR((F23-C23)/ABS(C23),0) -> -0.060139569 | J23: =ROUND(F23-Forecast!O28,1) -> 0
A24: Janitorial & Sanitation | B24: GM % | C24: =IFERROR(C21/C20,0) -> 0.28400041 | D24: =IFERROR(D21/D20,0) -> 0.2846663 | F24: =IFERROR(F21/F20,0) -> 0.28678917 | G24: =(F24-D24)*100 -> 0.21228711 | H24: =(F24-C24)*100 -> 0.27887554
A25: Janitorial & Sanitation | B25: Op Cost % | C25: =IFERROR(C22/C20,0) -> 0.19317775 | D25: =IFERROR(D22/D20,0) -> 0.1951773 | F25: =IFERROR(F22/F20,0) -> 0.19852199 | G25: =(F25-D25)*100 -> 0.33446925 | H25: =(F25-C25)*100 -> 0.53442392
A26: Janitorial & Sanitation | B26: PBITA % | C26: =IFERROR(C23/C20,0) -> 0.090822663 | D26: =IFERROR(D23/D20,0) -> 0.089489001 | F26: =IFERROR(F23/F20,0) -> 0.088267179 | G26: =(F26-D26)*100 -> -0.12218214 | H26: =(F26-C26)*100 -> -0.25554838
A27: Safety & PPE | B27: Sales | C27: 117479.6 | D27: 109493.4 | E27: =SUMIFS(Adjustments!F6:F27,Adjustments!B6:B27,A27) -> -1143.5 | F27: =D27+E27 -> 108349.9 | G27: =IFERROR((F27-D27)/ABS(D27),0) -> -0.010443552 | H27: =F27-C27 -> -9129.7 | I27: =IFERROR((F27-C27)/ABS(C27),0) -> -0.077713067 | J27: =ROUND(F27-Forecast!O31,1) -> 0
A28: Safety & PPE | B28: Gross Margin | C28: 35948.7 | D28: 33036.5 | E28: =SUMIFS(Adjustments!G6:G27,Adjustments!B6:B27,A28) -> -1664.2 | F28: =D28+E28 -> 31372.3 | G28: =IFERROR((F28-D28)/ABS(D28),0) -> -0.050374586 | H28: =F28-C28 -> -4576.4 | I28: =IFERROR((F28-C28)/ABS(C28),0) -> -0.12730363 | J28: =ROUND(F28-Forecast!O32,1) -> 0
A29: Safety & PPE | B29: Op Costs | C29: 22211.9 | D29: 21242 | E29: =SUMIFS(Adjustments!H6:H27,Adjustments!B6:B27,A29) -> 251.8 | F29: =D29+E29 -> 21493.8 | G29: =IFERROR((F29-D29)/ABS(D29),0) -> 0.011853874 | H29: =F29-C29 -> -718.1 | I29: =IFERROR((F29-C29)/ABS(C29),0) -> -0.032329517 | J29: =ROUND(F29-Forecast!O34,1) -> 0
A30: Safety & PPE | B30: PBITA | C30: =C28-C29 -> 13736.8 | D30: =D28-D29 -> 11794.5 | E30: =E28-E29 -> -1916 | F30: =F28-F29 -> 9878.5 | G30: =IFERROR((F30-D30)/ABS(D30),0) -> -0.1624486 | H30: =F30-C30 -> -3858.3 | I30: =IFERROR((F30-C30)/ABS(C30),0) -> -0.28087327 | J30: =ROUND(F30-Forecast!O36,1) -> 0
A31: Safety & PPE | B31: GM % | C31: =IFERROR(C28/C27,0) -> 0.30599951 | D31: =IFERROR(D28/D27,0) -> 0.30172138 | F31: =IFERROR(F28/F27,0) -> 0.28954618 | G31: =(F31-D31)*100 -> -1.2175199 | H31: =(F31-C31)*100 -> -1.6453326
A32: Safety & PPE | B32: Op Cost % | C32: =IFERROR(C29/C27,0) -> 0.18907027 | D32: =IFERROR(D29/D27,0) -> 0.19400256 | F32: =IFERROR(F29/F27,0) -> 0.19837397 | G32: =(F32-D32)*100 -> 0.43714108 | H32: =(F32-C32)*100 -> 0.93036991
A33: Safety & PPE | B33: PBITA % | C33: =IFERROR(C30/C27,0) -> 0.11692924 | D33: =IFERROR(D30/D27,0) -> 0.10771882 | F33: =IFERROR(F30/F27,0) -> 0.091172212 | G33: =(F33-D33)*100 -> -1.654661 | H33: =(F33-C33)*100 -> -2.5757026
A34: Retail Supplies | B34: Sales | C34: 77357.6 | D34: 76049.2 | E34: =SUMIFS(Adjustments!F6:F27,Adjustments!B6:B27,A34) -> -972.9 | F34: =D34+E34 -> 75076.3 | G34: =IFERROR((F34-D34)/ABS(D34),0) -> -0.012793034 | H34: =F34-C34 -> -2281.3 | I34: =IFERROR((F34-C34)/ABS(C34),0) -> -0.029490315 | J34: =ROUND(F34-Forecast!O39,1) -> 0
A35: Retail Supplies | B35: Gross Margin | C35: 17637.5 | D35: 17134.5 | E35: =SUMIFS(Adjustments!G6:G27,Adjustments!B6:B27,A35) -> -253.6 | F35: =D35+E35 -> 16880.9 | G35: =IFERROR((F35-D35)/ABS(D35),0) -> -0.014800549 | H35: =F35-C35 -> -756.6 | I35: =IFERROR((F35-C35)/ABS(C35),0) -> -0.042897236 | J35: =ROUND(F35-Forecast!O40,1) -> 0
A36: Retail Supplies | B36: Op Costs | C36: 15668.9 | D36: 15432.7 | E36: =SUMIFS(Adjustments!H6:H27,Adjustments!B6:B27,A36) -> 311 | F36: =D36+E36 -> 15743.7 | G36: =IFERROR((F36-D36)/ABS(D36),0) -> 0.020152015 | H36: =F36-C36 -> 74.8 | I36: =IFERROR((F36-C36)/ABS(C36),0) -> 0.0047737876 | J36: =ROUND(F36-Forecast!O42,1) -> 0
A37: Retail Supplies | B37: PBITA | C37: =C35-C36 -> 1968.6 | D37: =D35-D36 -> 1701.8 | E37: =E35-E36 -> -564.6 | F37: =F35-F36 -> 1137.2 | G37: =IFERROR((F37-D37)/ABS(D37),0) -> -0.33176637 | H37: =F37-C37 -> -831.4 | I37: =IFERROR((F37-C37)/ABS(C37),0) -> -0.42233059 | J37: =ROUND(F37-Forecast!O44,1) -> 0
A38: Retail Supplies | B38: GM % | C38: =IFERROR(C35/C34,0) -> 0.22799958 | D38: =IFERROR(D35/D34,0) -> 0.22530809 | F38: =IFERROR(F35/F34,0) -> 0.22484992 | G38: =(F38-D38)*100 -> -0.045817068 | H38: =(F38-C38)*100 -> -0.31496566
A39: Retail Supplies | B39: Op Cost % | C39: =IFERROR(C36/C34,0) -> 0.20255153 | D39: =IFERROR(D36/D34,0) -> 0.20293047 | F39: =IFERROR(F36/F34,0) -> 0.20970266 | G39: =(F39-D39)*100 -> 0.67721912 | H39: =(F39-C39)*100 -> 0.71511356
A40: Retail Supplies | B40: PBITA % | C40: =IFERROR(C37/C34,0) -> 0.025448049 | D40: =IFERROR(D37/D34,0) -> 0.022377619 | F40: =IFERROR(F37/F34,0) -> 0.015147257 | G40: =(F40-D40)*100 -> -0.72303618 | H40: =(F40-C40)*100 -> -1.0300792
A42: Percentage rows: change columns are shown in percentage points (pts). Op Costs: a positive change means higher cost (unfavorable).

Sheet Adjustments
A1: Operational Adjustments - Prior FCAST (Q2 6+6) to Current FCAST (Q3 9+3) - Full Year 2026
A2: USD $000s | Positive Sales/GM/PBITA = improvement; positive Op Costs = higher cost
A3: TRAINING DATA ONLY - Zava Supply Co. is a fictitious company. All names and numbers are invented for the Copilot Finance Controllers workshop.
A5: ID | B5: Business Unit | C5: Driver Category | D5: Description | E5: Months Affected | F5: Sales | G5: Gross Margin | H5: Op Costs | I5: PBITA
A6: ADJ-01 | B6: Foodservice Packaging | C6: New Customer | D6: Harbor Grill Group national account went live in July (Q2 forecast assumed a January 2027 start) | E6: Jul-Dec | F6: 11100 | G6: 2115.1 | H6: 2850.4 | I6: =G6-H6 -> -735.3
A7: ADJ-02 | B7: Foodservice Packaging | C7: Price / Cost | D7: Resin cost deflation on cups and clamshells passed through to customers | E7: Jul-Dec | F7: -552.6 | G7: 125.6 | H7: -52 | I7: =G7-H7 -> 177.6
A8: ADJ-03 | B8: Janitorial & Sanitation | C8: Volume | D8: Softer case volume at school and office-park customers (-2.5% vs -1% assumed) | E8: Jul-Dec | F8: -897.1 | G8: -255.2 | H8: -84.4 | I8: =G8-H8 -> -170.8
A9: ADJ-04 | B9: Janitorial & Sanitation | C9: New Customer | D9: Brightway Hospitals expanded to six additional sites | E9: Jul-Dec | F9: 586.7 | G9: 167 | H9: 55.2 | I9: =G9-H9 -> 111.8
A10: ADJ-05 | B10: Janitorial & Sanitation | C10: One-time | D10: Vendor rebate true-up received in September (one-time) | E10: Sep | F10: 0 | G10: 249.9 | H10: 0 | I10: =G10-H10 -> 249.9
A11: ADJ-06 | B11: Janitorial & Sanitation | C11: One-time | D11: Pricing & assortment consulting study in August (one-time) | E11: Aug | F11: 0 | G11: 0 | H11: 266 | I11: =G11-H11 -> -266
A12: ADJ-07 | B12: Safety & PPE | C12: Volume | D12: Summit Steelworks plant shutdown in July and August | E12: Jul-Aug | F12: -1143.5 | G12: -346.7 | H12: -106.4 | I12: =G12-H12 -> -240.3
A13: ADJ-08 | B13: Safety & PPE | C13: Cost Inflation | D13: Nitrile glove supplier cost increase not yet passed through to customers | E13: Jul-Dec | F13: 0 | G13: -1317.5 | H13: 0 | I13: =G13-H13 -> -1317.5
A14: ADJ-09 | B14: Safety & PPE | C14: Credit Risk | D14: Bad debt reserve for Ridgeline Fabrication (September) | E14: Sep | F14: 0 | G14: 0 | H14: 399.5 | I14: =G14-H14 -> -399.5
A15: ADJ-10 | B15: Safety & PPE | C15: Cost Saving | D15: Delivery route consolidation lowered freight and fuel cost | E15: Jul-Dec | F15: 0 | G15: 0 | H15: -122.6 | I15: =G15-H15 -> 122.6
A16: ADJ-11 | B16: Safety & PPE | C16: Timing | D16: Duplicate July utilities accrual; reversal planned for October (no full-year impact) | E16: Jul & Oct | F16: 0 | G16: 0 | H16: 0 | I16: =G16-H16 -> 0
A17: ADJ-12 | B17: Retail Supplies | C17: Lost Business | D17: Corner Mart moved to direct-from-manufacturer supply in August | E17: Aug-Dec | F17: -2157.7 | G17: -488.2 | H17: -202.4 | I17: =G17-H17 -> -285.8
... A27: ADJ-22 | B27: Retail Supplies | C27: Cost Saving | D27: Travel & entertainment running below plan | E27: Jul-Dec | F27: 0 | G27: 0 | H27: -36 | I27: =G27-H27 -> 36
D28: Total Operational Adjustments | F28: =SUM(F6:F27) -> 8120.6 | G28: =SUM(G6:G27) -> 484.6 | H28: =SUM(H6:H27) -> 3798.3 | I28: =SUM(I6:I27) -> -3313.7

Sheet Forecast
A1: Current Forecast (Q3 9+3) - FY2026 by Month
A2: USD $000s | Jan-Sep = Actual, Oct-Dec = FCAST
A3: TRAINING DATA ONLY - Zava Supply Co. is a fictitious company. All names and numbers are invented for the Copilot Finance Controllers workshop.
A5: Business Unit | B5: Metric | C5: January | D5: February | E5: March | F5: April | G5: May | H5: June | I5: July | J5: August | K5: September | L5: October | M5: November | N5: December | O5: Full Year
A6: Type | C6: Actual | D6: Actual | E6: Actual | F6: Actual | G6: Actual | H6: Actual | I6: Actual | J6: Actual | K6: Actual | L6: FCAST | M6: FCAST | N6: FCAST
A7: Consolidated | B7: Sales | C7: =C15+C23+C31+C39 -> 37522.3 | D7: =D15+D23+D31+D39 -> 36649.2 | E7: =E15+E23+E31+E39 -> 40120.1 | F7: =F15+F23+F31+F39 -> 40264.1 | G7: =G15+G23+G31+G39 -> 41056 | H7: =H15+H23+H31+H39 -> 41353.5 | I7: =I15+I23+I31+I39 -> 41113.4 | J7: =J15+J23+J31+J39 -> 41508.2 | ... N7: =N15+N23+N31+N39 -> 41309 | O7: =SUM(C7:N7) -> 486520.4
A8: Consolidated | B8: Gross Margin | C8: =C16+C24+C32+C40 -> 9926.8 | D8: =D16+D24+D32+D40 -> 9756.5 | E8: =E16+E24+E32+E40 -> 10701.1 | F8: =F16+F24+F32+F40 -> 10684.2 | G8: =G16+G24+G32+G40 -> 10809.8 | H8: =H16+H24+H32+H40 -> 10780.8 | I8: =I16+I24+I32+I40 -> 10561.1 | J8: =J16+J24+J32+J40 -> 10694.5 | ... N8: =N16+N24+N32+N40 -> 10609.4 | O8: =SUM(C8:N8) -> 127118.3
A9: Consolidated | B9: GM % | C9: =IFERROR(C8/C7,0) -> 0.26455734 | D9: =IFERROR(D8/D7,0) -> 0.26621318 | E9: =IFERROR(E8/E7,0) -> 0.26672665 | F9: =IFERROR(F8/F7,0) -> 0.26535301 | G9: =IFERROR(G8/G7,0) -> 0.26329404 | H9: =IFERROR(H8/H7,0) -> 0.26069861 | I9: =IFERROR(I8/I7,0) -> 0.25687732 | J9: =IFERROR(J8/J7,0) -> 0.25764789 | ... O9: =IFERROR(O8/O7,0) -> 0.26128051
A10: Consolidated | B10: Op Costs | C10: =C18+C26+C34+C42 -> 7455.8 | D10: =D18+D26+D34+D42 -> 7388 | E10: =E18+E26+E34+E42 -> 7694.4 | F10: =F18+F26+F34+F42 -> 7724.9 | G10: =G18+G26+G34+G42 -> 7839.6 | H10: =H18+H26+H34+H42 -> 7977.2 | I10: =I18+I26+I34+I42 -> 8454.5 | J10: =J18+J26+J34+J42 -> 8707.7 | ... N10: =N18+N26+N34+N42 -> 7960.6 | O10: =SUM(C10:N10) -> 96663.7
A11: Consolidated | B11: Op Cost % | C11: =IFERROR(C10/C7,0) -> 0.19870317 | D11: =IFERROR(D10/D7,0) -> 0.20158694 | E11: =IFERROR(E10/E7,0) -> 0.19178417 | F11: =IFERROR(F10/F7,0) -> 0.19185577 | G11: =IFERROR(G10/G7,0) -> 0.19094895 | H11: =IFERROR(H10/H7,0) -> 0.19290266 | I11: =IFERROR(I10/I7,0) -> 0.20563855 | J11: =IFERROR(J10/J7,0) -> 0.20978265 | ... O11: =IFERROR(O10/O7,0) -> 0.19868376
A12: Consolidated | B12: PBITA | C12: =C8-C10 -> 2471 | D12: =D8-D10 -> 2368.5 | E12: =E8-E10 -> 3006.7 | F12: =F8-F10 -> 2959.3 | G12: =G8-G10 -> 2970.2 | H12: =H8-H10 -> 2803.6 | I12: =I8-I10 -> 2106.6 | J12: =J8-J10 -> 1986.8 | ... N12: =N8-N10 -> 2648.8 | O12: =SUM(C12:N12) -> 30454.6
A13: Consolidated | B13: PBITA % | C13: =IFERROR(C12/C7,0) -> 0.065854172 | D13: =IFERROR(D12/D7,0) -> 0.06462624 | E13: =IFERROR(E12/E7,0) -> 0.074942485 | F13: =IFERROR(F12/F7,0) -> 0.073497235 | G13: =IFERROR(G12/G7,0) -> 0.07234509 | H13: =IFERROR(H12/H7,0) -> 0.067795954 | I13: =IFERROR(I12/I7,0) -> 0.051238769 | J13: =IFERROR(J12/J7,0) -> 0.047865241 | ... O13: =IFERROR(O12/O7,0) -> 0.062596759
A14: Consolidated | B14: Sales/Day | C14: =IFERROR(C7/21,0) -> 1786.7762 | D14: =IFERROR(D7/20,0) -> 1832.46 | E14: =IFERROR(E7/22,0) -> 1823.6409 | F14: =IFERROR(F7/22,0) -> 1830.1864 | G14: =IFERROR(G7/20,0) -> 2052.8 | H14: =IFERROR(H7/22,0) -> 1879.7045 | I14: =IFERROR(I7/22,0) -> 1868.7909 | J14: =IFERROR(J7/21,0) -> 1976.581 | K14: =IFERROR(K7/21,0) -> 1995.2333 | L14: =IFERROR(L7/22,0) -> 1919.5455 | M14: =IFERROR(M7/19,0) -> 2183.9316 | N14: =IFERROR(N7/22,0) -> 1877.6818 | O14: =IFERROR(O7/254,0) -> 1915.4346
A15: Foodservice Packaging | B15: Sales | C15: 13664.2 | D15: 13486.1 | E15: 14747.3 | F15: 14652.1 | G15: 15277.9 | H15: 15250.6 | I15: 16380.7 | J15: 16613.1 | K15: 16662.7 | L15: 16461.7 | M15: 16061.2 | N15: 16043.1 | O15: =SUM(C15:N15) -> 185300.7
A16: Foodservice Packaging | B16: Gross Margin | C16: 3341.6 | D16: 3305.1 | E16: 3635 | F16: 3570.2 | G16: 3699.2 | H16: 3766.7 | I16: 3958.9 | J16: 4026.4 | K16: 4052.9 | L16: 3951.4 | M16: 3896.2 | N16: 3879.6 | O16: =SUM(C16:N16) -> 45083.2
A17: Foodservice Packaging | B17: GM % | C17: =IFERROR(C16/C15,0) -> 0.24455146 | D17: =IFERROR(D16/D15,0) -> 0.24507456 | E17: =IFERROR(E16/E15,0) -> 0.2464858 | F17: =IFERROR(F16/F15,0) -> 0.24366473 | G17: =IFERROR(G16/G15,0) -> 0.24212752 | H17: =IFERROR(H16/H15,0) -> 0.246987 | I17: =IFERROR(I16/I15,0) -> 0.24168076 | J17: =IFERROR(J16/J15,0) -> 0.24236295 | ... O17: =IFERROR(O16/O15,0) -> 0.24329752
A18: Foodservice Packaging | B18: Op Costs | C18: 2663.7 | D18: 2638 | E18: 2761.4 | F18: 2751.3 | G18: 2819.9 | H18: 2856.3 | I18: 3395.9 | J18: 3451.2 | K18: 3439.4 | L18: 3227.9 | M18: 3071.6 | N18: 2965 | O18: =SUM(C18:N18) -> 36041.6
A19: Foodservice Packaging | B19: Op Cost % | C19: =IFERROR(C18/C15,0) -> 0.19494006 | D19: =IFERROR(D18/D15,0) -> 0.19560881 | E19: =IFERROR(E18/E15,0) -> 0.18724784 | F19: =IFERROR(F18/F15,0) -> 0.18777513 | G19: =IFERROR(G18/G15,0) -> 0.1845738 | H19: =IFERROR(H18/H15,0) -> 0.18729099 | I19: =IFERROR(I18/I15,0) -> 0.20731104 | J19: =IFERROR(J18/J15,0) -> 0.20773968 | ... O19: =IFERROR(O18/O15,0) -> 0.19450331
A20: Foodservice Packaging | B20: PBITA | C20: =C16-C18 -> 677.9 | D20: =D16-D18 -> 667.1 | E20: =E16-E18 -> 873.6 | F20: =F16-F18 -> 818.9 | G20: =G16-G18 -> 879.3 | H20: =H16-H18 -> 910.4 | I20: =I16-I18 -> 563 | J20: =J16-J18 -> 575.2 | ... N20: =N16-N18 -> 914.6 | O20: =SUM(C20:N20) -> 9041.6
A21: Foodservice Packaging | B21: PBITA % | C21: =IFERROR(C20/C15,0) -> 0.049611393 | D21: =IFERROR(D20/D15,0) -> 0.049465746 | E21: =IFERROR(E20/E15,0) -> 0.059237962 | F21: =IFERROR(F20/F15,0) -> 0.055889599 | G21: =IFERROR(G20/G15,0) -> 0.057553721 | H21: =IFERROR(H20/H15,0) -> 0.059696012 | I21: =IFERROR(I20/I15,0) -> 0.034369716 | J21: =IFERROR(J20/J15,0) -> 0.034623279 | ... O21: =IFERROR(O20/O15,0) -> 0.048794203
A22: Foodservice Packaging | B22: Sales/Day | C22: =IFERROR(C15/21,0) -> 650.67619 | D22: =IFERROR(D15/20,0) -> 674.305 | E22: =IFERROR(E15/22,0) -> 670.33182 | F22: =IFERROR(F15/22,0) -> 666.00455 | G22: =IFERROR(G15/20,0) -> 763.895 | H22: =IFERROR(H15/22,0) -> 693.20909 | I22: =IFERROR(I15/22,0) -> 744.57727 | J22: =IFERROR(J15/21,0) -> 791.1 | K22: =IFERROR(K15/21,0) -> 793.4619 | L22: =IFERROR(L15/22,0) -> 748.25909 | M22: =IFERROR(M15/19,0) -> 845.32632 | N22: =IFERROR(N15/22,0) -> 729.23182 | O22: =IFERROR(O15/254,0) -> 729.53031
A23: Janitorial & Sanitation | B23: Sales | C23: 9103.1 | D23: 8825.7 | E23: 9498.8 | F23: 9707.6 | G23: 10062.9 | H23: 10372 | I23: 10070.9 | J23: 10311.7 | K23: 10172.1 | L23: 10219.4 | M23: 9810.7 | N23: 9638.6 | O23: =SUM(C23:N23) -> 117793.5
A24: Janitorial & Sanitation | B24: Gross Margin | C24: 2576.8 | D24: 2530.9 | E24: 2699.2 | F24: 2770.4 | G24: 2852.3 | H24: 2971.5 | I24: 2853.1 | J24: 2915.4 | K24: 3150.9 | L24: 2912.7 | M24: 2814.8 | N24: 2733.9 | O24: =SUM(C24:N24) -> 33781.9
A25: Janitorial & Sanitation | B25: GM % | C25: =IFERROR(C24/C23,0) -> 0.28306841 | D25: =IFERROR(D24/D23,0) -> 0.28676479 | E25: =IFERROR(E24/E23,0) -> 0.28416221 | F25: =IFERROR(F24/F23,0) -> 0.28538465 | G25: =IFERROR(G24/G23,0) -> 0.28344712 | H25: =IFERROR(H24/H23,0) -> 0.28649248 | I25: =IFERROR(I24/I23,0) -> 0.28330139 | J25: =IFERROR(J24/J23,0) -> 0.28272739 | ... O25: =IFERROR(O24/O23,0) -> 0.28678917
A26: Janitorial & Sanitation | B26: Op Costs | C26: 1830 | D26: 1822.5 | E26: 1869.3 | F26: 1882.6 | G26: 1941.6 | H26: 1999.4 | I26: 1976.3 | J26: 2263.7 | K26: 1975.6 | L26: 1968.9 | M26: 1935.9 | N26: 1918.8 | O26: =SUM(C26:N26) -> 23384.6
A27: Janitorial & Sanitation | B27: Op Cost % | C27: =IFERROR(C26/C23,0) -> 0.20103042 | D27: =IFERROR(D26/D23,0) -> 0.2064992 | E27: =IFERROR(E26/E23,0) -> 0.19679328 | F27: =IFERROR(F26/F23,0) -> 0.19393053 | G27: =IFERROR(G26/G23,0) -> 0.19294637 | H27: =IFERROR(H26/H23,0) -> 0.19276899 | I27: =IFERROR(I26/I23,0) -> 0.19623867 | J27: =IFERROR(J26/J23,0) -> 0.21952733 | ... O27: =IFERROR(O26/O23,0) -> 0.19852199
A28: Janitorial & Sanitation | B28: PBITA | C28: =C24-C26 -> 746.8 | D28: =D24-D26 -> 708.4 | E28: =E24-E26 -> 829.9 | F28: =F24-F26 -> 887.8 | G28: =G24-G26 -> 910.7 | H28: =H24-H26 -> 972.1 | I28: =I24-I26 -> 876.8 | J28: =J24-J26 -> 651.7 | ... N28: =N24-N26 -> 815.1 | O28: =SUM(C28:N28) -> 10397.3
A29: Janitorial & Sanitation | B29: PBITA % | C29: =IFERROR(C28/C23,0) -> 0.082037987 | D29: =IFERROR(D28/D23,0) -> 0.080265588 | E29: =IFERROR(E28/E23,0) -> 0.087368931 | F29: =IFERROR(F28/F23,0) -> 0.091454118 | G29: =IFERROR(G28/G23,0) -> 0.09050075 | H29: =IFERROR(H28/H23,0) -> 0.093723486 | I29: =IFERROR(I28/I23,0) -> 0.087062725 | J29: =IFERROR(J28/J23,0) -> 0.063200054 | ... O29: =IFERROR(O28/O23,0) -> 0.088267179
A30: Janitorial & Sanitation | B30: Sales/Day | C30: =IFERROR(C23/21,0) -> 433.48095 | D30: =IFERROR(D23/20,0) -> 441.285 | E30: =IFERROR(E23/22,0) -> 431.76364 | F30: =IFERROR(F23/22,0) -> 441.25455 | G30: =IFERROR(G23/20,0) -> 503.145 | H30: =IFERROR(H23/22,0) -> 471.45455 | I30: =IFERROR(I23/22,0) -> 457.76818 | J30: =IFERROR(J23/21,0) -> 491.03333 | K30: =IFERROR(K23/21,0) -> 484.38571 | L30: =IFERROR(L23/22,0) -> 464.51818 | M30: =IFERROR(M23/19,0) -> 516.35263 | N30: =IFERROR(N23/22,0) -> 438.11818 | O30: =IFERROR(O23/254,0) -> 463.75394
A31: Safety & PPE | B31: Sales | C31: 9040.7 | D31: 8722 | E31: 9736.2 | F31: 9677.3 | G31: 9287.6 | H31: 9306.6 | I31: 8522.9 | J31: 8588.3 | K31: 9115.5 | L31: 8988.6 | M31: 8764.7 | N31: 8599.5 | O31: =SUM(C31:N31) -> 108349.9
A32: Safety & PPE | B32: Gross Margin | C32: 2738.7 | D32: 2666.5 | E32: 2982.8 | F32: 2945.6 | G32: 2816.4 | H32: 2586.9 | I32: 2366.2 | J32: 2392.4 | K32: 2530.5 | L32: 2493.5 | M32: 2452.7 | N32: 2400.1 | O32: =SUM(C32:N32) -> 31372.3
A33: Safety & PPE | B33: GM % | C33: =IFERROR(C32/C31,0) -> 0.30293008 | D33: =IFERROR(D32/D31,0) -> 0.30572116 | E33: =IFERROR(E32/E31,0) -> 0.30636182 | F33: =IFERROR(F32/F31,0) -> 0.30438242 | G33: =IFERROR(G32/G31,0) -> 0.30324303 | H33: =IFERROR(H32/H31,0) -> 0.27796403 | I33: =IFERROR(I32/I31,0) -> 0.27762851 | J33: =IFERROR(J32/J31,0) -> 0.27856502 | ... O33: =IFERROR(O32/O31,0) -> 0.28954618
A34: Safety & PPE | B34: Op Costs | C34: 1745.4 | D34: 1719.8 | E34: 1810.9 | F34: 1818 | G34: 1783.6 | H34: 1806.2 | I34: 1790.1 | J34: 1719.3 | K34: 2157.8 | L34: 1680.3 | M34: 1747.1 | N34: 1715.3 | O34: =SUM(C34:N34) -> 21493.8
A35: Safety & PPE | B35: Op Cost % | C35: =IFERROR(C34/C31,0) -> 0.19306027 | D35: =IFERROR(D34/D31,0) -> 0.19717955 | E35: =IFERROR(E34/E31,0) -> 0.18599659 | F35: =IFERROR(F34/F31,0) -> 0.18786232 | G35: =IFERROR(G34/G31,0) -> 0.192041 | H35: =IFERROR(H34/H31,0) -> 0.19407732 | I35: =IFERROR(I34/I31,0) -> 0.21003414 | J35: =IFERROR(J34/J31,0) -> 0.20019096 | ... O35: =IFERROR(O34/O31,0) -> 0.19837397
A36: Safety & PPE | B36: PBITA | C36: =C32-C34 -> 993.3 | D36: =D32-D34 -> 946.7 | E36: =E32-E34 -> 1171.9 | F36: =F32-F34 -> 1127.6 | G36: =G32-G34 -> 1032.8 | H36: =H32-H34 -> 780.7 | I36: =I32-I34 -> 576.1 | J36: =J32-J34 -> 673.1 | ... N36: =N32-N34 -> 684.8 | O36: =SUM(C36:N36) -> 9878.5
A37: Safety & PPE | B37: PBITA % | C37: =IFERROR(C36/C31,0) -> 0.10986981 | D37: =IFERROR(D36/D31,0) -> 0.10854162 | E37: =IFERROR(E36/E31,0) -> 0.12036523 | F37: =IFERROR(F36/F31,0) -> 0.1165201 | G37: =IFERROR(G36/G31,0) -> 0.11120203 | H37: =IFERROR(H36/H31,0) -> 0.083886704 | I37: =IFERROR(I36/I31,0) -> 0.067594363 | J37: =IFERROR(J36/J31,0) -> 0.078374067 | ... O37: =IFERROR(O36/O31,0) -> 0.091172212
A38: Safety & PPE | B38: Sales/Day | C38: =IFERROR(C31/21,0) -> 430.50952 | D38: =IFERROR(D31/20,0) -> 436.1 | E38: =IFERROR(E31/22,0) -> 442.55455 | F38: =IFERROR(F31/22,0) -> 439.87727 | G38: =IFERROR(G31/20,0) -> 464.38 | H38: =IFERROR(H31/22,0) -> 423.02727 | I38: =IFERROR(I31/22,0) -> 387.40455 | J38: =IFERROR(J31/21,0) -> 408.96667 | K38: =IFERROR(K31/21,0) -> 434.07143 | L38: =IFERROR(L31/22,0) -> 408.57273 | M38: =IFERROR(M31/19,0) -> 461.3 | N38: =IFERROR(N31/22,0) -> 390.88636 | O38: =IFERROR(O31/254,0) -> 426.57441
A39: Retail Supplies | B39: Sales | C39: 5714.3 | D39: 5615.4 | E39: 6137.8 | F39: 6227.1 | G39: 6427.6 | H39: 6424.3 | I39: 6138.9 | J39: 5995.1 | K39: 5949.6 | L39: 6560.3 | M39: 6858.1 | N39: 7027.8 | O39: =SUM(C39:N39) -> 75076.3
A40: Retail Supplies | B40: Gross Margin | C40: 1269.7 | D40: 1254 | E40: 1384.1 | F40: 1398 | G40: 1441.9 | H40: 1455.7 | I40: 1382.9 | J40: 1360.3 | K40: 1318.9 | L40: 1476.5 | M40: 1543.1 | N40: 1595.8 | O40: =SUM(C40:N40) -> 16880.9
A41: Retail Supplies | B41: GM % | C41: =IFERROR(C40/C39,0) -> 0.22219694 | D41: =IFERROR(D40/D39,0) -> 0.22331446 | E41: =IFERROR(E40/E39,0) -> 0.22550425 | F41: =IFERROR(F40/F39,0) -> 0.22450258 | G41: =IFERROR(G40/G39,0) -> 0.22432945 | H41: =IFERROR(H40/H39,0) -> 0.22659278 | I41: =IFERROR(I40/I39,0) -> 0.22526837 | J41: =IFERROR(J40/J39,0) -> 0.22690197 | ... O41: =IFERROR(O40/O39,0) -> 0.22484992
...

Sheet Variances
A1: Forecast Change Commentary - Prior FCAST (Q2) to Current FCAST (Q3)
A2: Draft with Copilot, then edit. You own the final narrative.
A3: TRAINING DATA ONLY - Zava Supply Co. is a fictitious company. All names and numbers are invented for the Copilot Finance Controllers workshop.
A5: Business Unit | B5: Metric | C5: Prior FCAST | D5: Current FCAST | E5: Change $ | F5: Change % | G5: Key drivers (Copilot draft) | H5: My color commentary / context | I5: Validated? (Y/N)
A6: Consolidated | B6: Sales | C6: =Overview!D6 -> 478399.8 | D6: =Overview!F6 -> 486520.4 | E6: =D6-C6 -> 8120.6 | F6: =IFERROR((D6-C6)/ABS(C6),0) -> 0.016974505
A7: Consolidated | B7: Gross Margin | C7: =Overview!D7 -> 126633.7 | D7: =Overview!F7 -> 127118.3 | E7: =D7-C7 -> 484.6 | F7: =IFERROR((D7-C7)/ABS(C7),0) -> 0.0038267854
A8: Consolidated | B8: Op Costs | C8: =Overview!D8 -> 92865.4 | D8: =Overview!F8 -> 96663.7 | E8: =D8-C8 -> 3798.3 | F8: =IFERROR((D8-C8)/ABS(C8),0) -> 0.040901132
A9: Consolidated | B9: PBITA | C9: =Overview!D9 -> 33768.3 | D9: =Overview!F9 -> 30454.6 | E9: =D9-C9 -> -3313.7 | F9: =IFERROR((D9-C9)/ABS(C9),0) -> -0.098130495
A10: Foodservice Packaging | B10: Sales | C10: =Overview!D13 -> 174753.3 | D10: =Overview!F13 -> 185300.7 | E10: =D10-C10 -> 10547.4 | F10: =IFERROR((D10-C10)/ABS(C10),0) -> 0.060355942
A11: Foodservice Packaging | B11: Gross Margin | C11: =Overview!D14 -> 42842.5 | D11: =Overview!F14 -> 45083.2 | E11: =D11-C11 -> 2240.7 | F11: =IFERROR((D11-C11)/ABS(C11),0) -> 0.052300869
A12: Foodservice Packaging | B12: Op Costs | C12: =Overview!D15 -> 33139.5 | D12: =Overview!F15 -> 36041.6 | E12: =D12-C12 -> 2902.1 | F12: =IFERROR((D12-C12)/ABS(C12),0) -> 0.087572233
A13: Foodservice Packaging | B13: PBITA | C13: =Overview!D16 -> 9703 | D13: =Overview!F16 -> 9041.6 | E13: =D13-C13 -> -661.4 | F13: =IFERROR((D13-C13)/ABS(C13),0) -> -0.068164485
A14: Janitorial & Sanitation | B14: Sales | C14: =Overview!D20 -> 118103.9 | D14: =Overview!F20 -> 117793.5 | E14: =D14-C14 -> -310.4 | F14: =IFERROR((D14-C14)/ABS(C14),0) -> -0.0026281943
A15: Janitorial & Sanitation | B15: Gross Margin | C15: =Overview!D21 -> 33620.2 | D15: =Overview!F21 -> 33781.9 | E15: =D15-C15 -> 161.7 | F15: =IFERROR((D15-C15)/ABS(C15),0) -> 0.0048096085
A16: Janitorial & Sanitation | B16: Op Costs | C16: =Overview!D22 -> 23051.2 | D16: =Overview!F22 -> 23384.6 | E16: =D16-C16 -> 333.4 | F16: =IFERROR((D16-C16)/ABS(C16),0) -> 0.014463455
A17: Janitorial & Sanitation | B17: PBITA | C17: =Overview!D23 -> 10569 | D17: =Overview!F23 -> 10397.3 | E17: =D17-C17 -> -171.7 | F17: =IFERROR((D17-C17)/ABS(C17),0) -> -0.016245624
A18: Safety & PPE | B18: Sales | C18: =Overview!D27 -> 109493.4 | D18: =Overview!F27 -> 108349.9 | E18: =D18-C18 -> -1143.5 | F18: =IFERROR((D18-C18)/ABS(C18),0) -> -0.010443552
A19: Safety & PPE | B19: Gross Margin | C19: =Overview!D28 -> 33036.5 | D19: =Overview!F28 -> 31372.3 | E19: =D19-C19 -> -1664.2 | F19: =IFERROR((D19-C19)/ABS(C19),0) -> -0.050374586
A20: Safety & PPE | B20: Op Costs | C20: =Overview!D29 -> 21242 | D20: =Overview!F29 -> 21493.8 | E20: =D20-C20 -> 251.8 | F20: =IFERROR((D20-C20)/ABS(C20),0) -> 0.011853874
A21: Safety & PPE | B21: PBITA | C21: =Overview!D30 -> 11794.5 | D21: =Overview!F30 -> 9878.5 | E21: =D21-C21 -> -1916 | F21: =IFERROR((D21-C21)/ABS(C21),0) -> -0.1624486
A22: Retail Supplies | B22: Sales | C22: =Overview!D34 -> 76049.2 | D22: =Overview!F34 -> 75076.3 | E22: =D22-C22 -> -972.9 | F22: =IFERROR((D22-C22)/ABS(C22),0) -> -0.012793034
A23: Retail Supplies | B23: Gross Margin | C23: =Overview!D35 -> 17134.5 | D23: =Overview!F35 -> 16880.9 | E23: =D23-C23 -> -253.6 | F23: =IFERROR((D23-C23)/ABS(C23),0) -> -0.014800549
A24: Retail Supplies | B24: Op Costs | C24: =Overview!D36 -> 15432.7 | D24: =Overview!F36 -> 15743.7 | E24: =D24-C24 -> 311 | F24: =IFERROR((D24-C24)/ABS(C24),0) -> 0.020152015
A25: Retail Supplies | B25: PBITA | C25: =Overview!D37 -> 1701.8 | D25: =Overview!F37 -> 1137.2 | E25: =D25-C25 -> -564.6 | F25: =IFERROR((D25-C25)/ABS(C25),0) -> -0.33176637

Sheet R&Os
A1: Risks & Opportunities - Q4 2026 (NOT included in Current FCAST)
A2: USD $000s | PBITA impact | Weighted = Impact x Probability
A3: TRAINING DATA ONLY - Zava Supply Co. is a fictitious company. All names and numbers are invented for the Copilot Finance Controllers workshop.
A5: ID | B5: Business Unit | C5: Type | D5: Description | E5: PBITA Impact (unweighted) | F5: Probability | G5: Weighted Impact | H5: Timing | I5: Owner | J5: Next step
A6: RO-01 | B6: Safety & PPE | C6: Risk | D6: Ridgeline Fabrication financial distress deepens; additional reserve beyond the September provision | E6: -250 | F6: 0.4 | G6: =E6*F6 -> -100 | H6: Q4 | I6: BU Controller | J6: Credit review with AR team
A7: RO-02 | B7: Safety & PPE | C7: Risk | D7: Nitrile glove price increase to customers delayed until January | E7: -300 | F7: 0.5 | G7: =E7*F7 -> -150 | H7: Nov-Dec | I7: BU Pricing Lead | J7: Confirm customer notice dates
A8: RO-03 | B8: Safety & PPE | C8: Opportunity | D8: Keystone Construction and Bluewater Utilities accept nitrile pass-through in November | E8: 180 | F8: 0.6 | G8: =E8*F8 -> 108 | H8: Nov-Dec | I8: BU Sales Director | J8: Track acceptance letters
A9: RO-04 | B9: Foodservice Packaging | C9: Opportunity | D9: Harbor Grill Group phase 2 (additional 120 restaurants) starts in December | E9: 140 | F9: 0.3 | G9: =E9*F9 -> 42 | H9: Dec | I9: National Accounts | J9: Confirm go-live date
A10: RO-05 | B10: Foodservice Packaging | C10: Risk | D10: Onboarding overtime continues through December | E10: -120 | F10: 0.5 | G10: =E10*F10 -> -60 | H10: Dec | I10: DC Operations Manager | J10: Review labor plan weekly
A11: RO-06 | B11: Janitorial & Sanitation | C11: Opportunity | D11: Q4 vendor rebate tier achieved on can liners | E11: 150 | F11: 0.4 | G11: =E11*F11 -> 60 | H11: Dec | I11: Purchasing | J11: Monitor purchase volume vs tier
A12: RO-07 | B12: Janitorial & Sanitation | C12: Opportunity | D12: Flu-season demand at Brightway Hospitals | E12: 90 | F12: 0.5 | G12: =E12*F12 -> 45 | H12: Nov-Dec | I12: BU Sales Director | J12: Agree stock levels
A13: RO-08 | B13: Retail Supplies | C13: Risk | D13: Holiday program sell-through below commitments | E13: -110 | F13: 0.35 | G13: =E13*F13 -> -38.5 | H13: Nov-Dec | I13: BU Controller | J13: Weekly POS review
A14: RO-09 | B14: All | C14: Risk | D14: ERP go-live slips; consultant extension required | E14: -160 | F14: 0.3 | G14: =E14*F14 -> -48 | H14: Dec | I14: IT Finance Partner | J14: Steering committee decision
D15: Net risks & opportunities | E15: =SUM(E6:E14) -> -380 | G15: =SUM(G6:G14) -> -141.5

Sheet Billing Days
A1: Zava Supply Co. - Billing Days & Daily Reported Sales - Consolidated
A2: USD $000s | Billing days = weekdays less company holidays
A3: TRAINING DATA ONLY - Zava Supply Co. is a fictitious company. All names and numbers are invented for the Copilot Finance Controllers workshop.
A5: Line | B5: January | C5: February | D5: March | E5: April | F5: May | G5: June | H5: July | I5: August | J5: September | K5: October | L5: November | M5: December | N5: Full Year
A6: Reported Sales 2026 (Actual / FCAST) | B6: 37522.3 | C6: 36649.2 | D6: 40120.1 | E6: 40264.1 | F6: 41056 | G6: 41353.5 | H6: 41113.4 | I6: 41508.2 | J6: 41899.9 | K6: 42230 | L6: 41494.7 | M6: 41309 | N6: =SUM(B6:M6) -> 486520.4
A7: Days 2026 | B7: 21 | C7: 20 | D7: 22 | E7: 22 | F7: 20 | G7: 22 | H7: 22 | I7: 21 | J7: 21 | K7: 22 | L7: 19 | M7: 22 | N7: =SUM(B7:M7) -> 254
A8: Daily Reported Sales 2026 | B8: =IF(B6="","",B6/B7) -> 1786.7762 | C8: =IF(C6="","",C6/C7) -> 1832.46 | D8: =IF(D6="","",D6/D7) -> 1823.6409 | E8: =IF(E6="","",E6/E7) -> 1830.1864 | F8: =IF(F6="","",F6/F7) -> 2052.8 | G8: =IF(G6="","",G6/G7) -> 1879.7045 | H8: =IF(H6="","",H6/H7) -> 1868.7909 | I8: =IF(I6="","",I6/I7) -> 1976.581 | ... M8: =IF(M6="","",M6/M7) -> 1877.6818 | N8: =N6/N7 -> 1915.4346
A9: Budget Sales 2026 | B9: 38510.8 | C9: 37650.9 | D9: 41080.7 | E9: 41208.8 | F9: 42143.6 | G9: 42700.6 | H9: 41971.3 | I9: 42186.8 | J9: 41279.1 | K9: 42351.2 | L9: 41047.8 | M9: 41060.8 | N9: =SUM(B9:M9) -> 493192.4
A10: Daily Budget Sales 2026 | B10: =IF(B9="","",B9/B7) -> 1833.8476 | C10: =IF(C9="","",C9/C7) -> 1882.545 | D10: =IF(D9="","",D9/D7) -> 1867.3045 | E10: =IF(E9="","",E9/E7) -> 1873.1273 | F10: =IF(F9="","",F9/F7) -> 2107.18 | G10: =IF(G9="","",G9/G7) -> 1940.9364 | H10: =IF(H9="","",H9/H7) -> 1907.7864 | I10: =IF(I9="","",I9/I7) -> 2008.8952 | ... M10: =IF(M9="","",M9/M7) -> 1866.4 | N10: =N9/N7 -> 1941.7024
A11: Reported Sales 2025 | B11: 37029.5 | C11: 36202.8 | D11: 39500.6 | E11: 39623.9 | F11: 40522.6 | G11: 41058.3 | H11: 40357 | I11: 40564.1 | J11: 39691.3 | K11: 40722.3 | L11: 39469.1 | M11: 39481.6 | N11: =SUM(B11:M11) -> 474223.1
A12: Days 2025 | B12: 22 | C12: 20 | D12: 21 | E12: 22 | F12: 21 | G12: 21 | H12: 22 | I12: 21 | J12: 21 | K12: 23 | L12: 18 | M12: 22 | N12: =SUM(B12:M12) -> 254
A13: Daily Reported Sales 2025 | B13: =IF(B11="","",B11/B12) -> 1683.1591 | C13: =IF(C11="","",C11/C12) -> 1810.14 | D13: =IF(D11="","",D11/D12) -> 1880.981 | E13: =IF(E11="","",E11/E12) -> 1801.0864 | F13: =IF(F11="","",F11/F12) -> 1929.6476 | G13: =IF(G11="","",G11/G12) -> 1955.1571 | H13: =IF(H11="","",H11/H12) -> 1834.4091 | I13: =IF(I11="","",I11/I12) -> 1931.6238 | ... M13: =IF(M11="","",M11/M12) -> 1794.6182 | N13: =N11/N12 -> 1867.0201
