Workbook

Sheet {HFM Defaults}
A2: Connection | B2: WSFN|HFM|HFM|ZAVALIVE|ZAVALIVE | C2: WSFN|HFM|HFM|ZAVALIVE|ZAVALIVE | D2: WSFN|HFM|HFM|ZAVALIVE|ZAVALIVE | E2: WSFN|HFM|HFM|ZAVALIVE|ZAVALIVE
A3: Scenario# | B3: ACTUAL | C3: ACTUAL | D3: ACTUAL | E3: ACTUAL
A4: Year#
A5: Period# | B5: [YEAR] | C5: [YEAR] | D5: [YEAR] | E5: [YEAR]
A6: View# | B6: <Scenario View> | C6: <Scenario View> | D6: <Scenario View> | E6: <Scenario View>
A7: Entity# | B7: [None] | C7: [None] | D7: [None] | E7: [None]
A8: Value# | B8: USD Total | C8: USD Total | D8: USD Total | E8: USD Total
A9: Account#
A10: ICP# | B10: [ICP Top] | C10: [ICP Top] | D10: [ICP Top] | E10: [ICP Top]
A11: Custom1# | B11: TotalC1 | C11: TotalC1 | D11: TotalC1 | E11: TotalC1
A12: Custom2# | B12: TotalC2 | C12: TotalC2 | D12: TotalC2 | E12: TotalC2
A13: Custom3# | B13: TotalC3 | C13: TotalC3 | D13: TotalC3 | E13: TotalC3
A14: Custom4# | B14: TotalC4 | C14: TotalC4 | D14: TotalC4 | E14: TotalC4
B15: TRAINING DATA ONLY - Zava Safety and all business names and numbers are fictitious. Layout mirrors a typical HFM / Cognos reporting pack.
B16: HFM entity name: | D16: SAFECON_2DISP | G16: Current ME | J16: Next ME | N16: Period | O16: Month-end
B17: Current month-end period: | D17: P09 | G17: Jan | H17: Actual | J17: Jan | K17: Actual | N17: P01
B18: Next month-end period: | D18: P10 | G18: Feb | H18: Actual | J18: Feb | K18: Actual | N18: P02
B19: Current month-end date: | D19: 2026-09-30 | G19: Mar | H19: Actual | J19: Mar | K19: Actual | N19: P03
B20: Forecast reference for actual | D20: FCAST09 | G20: Apr | H20: Actual | J20: Apr | K20: Actual | N20: P04
B21: Next month-end date: | D21: 2026-10-31 | G21: May | H21: Actual | J21: May | K21: Actual | N21: P05
B22: Forecast reference for actual | D22: FCAST10 | G22: Jun | H22: Actual | J22: Jun | K22: Actual | N22: P06
G23: Jul | H23: Actual | J23: Jul | K23: Actual | N23: P07
G24: Aug | H24: Actual | J24: Aug | K24: Actual | N24: P08
B25: Current Period Estimate or Retrieve: | D25: Retrieve | G25: Sep | H25: FCAST09 | J25: Sep | K25: Actual | N25: P09
B26: Reported or Excl ACQ: | D26: Reported | G26: Oct | H26: FCAST09 | J26: Oct | K26: FCAST10 | N26: P10
G27: Nov | H27: FCAST09 | J27: Nov | K27: FCAST10 | N27: P11
G28: Dec | H28: FCAST09 | J28: Dec | K28: FCAST10 | N28: P12

Sheet Billing Days
A1: Billing Days & Daily Sales
A2: TRAINING DATA ONLY - Zava Safety and all business names and numbers are fictitious. Layout mirrors a typical HFM / Cognos reporting pack.
B4: January | C4: February | D4: March | E4: April | F4: May | G4: June | H4: July | I4: August | J4: September | K4: October | L4: November | M4: December | N4: Full Year
A5: Reported Sales - FCAST10 (Actual Jan-Sep) | B5: 49776.7 | C5: 49033.4 | D5: 52588.4 | E5: 56881.9 | F5: 51833.5 | G5: 54124.1 | H5: 53826.7 | I5: 52681.3 | J5: 53640.4 | K5: 54420.3 | L5: 50066 | M5: 55284.2 | N5: =SUM(B5:M5) -> 634156.9
A6: Days 2026 | B6: 21 | C6: 20 | D6: 22 | E6: 22 | F6: 20 | G6: 22 | H6: 22 | I6: 21 | J6: 21 | K6: 22 | L6: 19 | M6: 22 | N6: =SUM(B6:M6) -> 254
A7: Daily Reported Sales | B7: =B5/B6 -> 2370.319 | C7: =C5/C6 -> 2451.67 | D7: =D5/D6 -> 2390.3818 | E7: =E5/E6 -> 2585.5409 | F7: =F5/F6 -> 2591.675 | G7: =G5/G6 -> 2460.1864 | H7: =H5/H6 -> 2446.6682 | I7: =I5/I6 -> 2508.6333 | ... N7: =N5/N6 -> 2496.6807
A8: Budget Sales 2026 | B8: 49083 | C8: 48050 | D8: 51666.4 | E8: 55799.9 | F8: 50633.4 | G8: 53216.8 | H8: 52699.6 | I8: 51666.6 | J8: 50633.2 | K8: 54249.8 | L8: 49083.1 | M8: 53216.3 | N8: =SUM(B8:M8) -> 619998.1
A9: Daily Budget Sales | B9: =B8/B6 -> 2337.2857 | C9: =C8/C6 -> 2402.5 | D9: =D8/D6 -> 2348.4727 | E9: =E8/E6 -> 2536.3591 | F9: =F8/F6 -> 2531.67 | G9: =G8/G6 -> 2418.9455 | H9: =H8/H6 -> 2395.4364 | I9: =I8/I6 -> 2460.3143 | ... N9: =N8/N6 -> 2440.9374
A10: Reported Sales 2025 | B10: 46990.7 | C10: 45717.1 | D10: 49328.6 | E10: 53313.8 | F10: 48140.4 | G10: 50828.2 | H10: 50581.7 | I10: 48966.9 | J10: 48517.7 | K10: 51865.9 | L10: 46746 | M10: 50915.4 | N10: =SUM(B10:M10) -> 591912.4
A11: Days 2025 | B11: 22 | C11: 20 | D11: 21 | E11: 22 | F11: 21 | G11: 21 | H11: 22 | I11: 21 | J11: 21 | K11: 23 | L11: 18 | M11: 22 | N11: =SUM(B11:M11) -> 254
A12: Daily Reported Sales 2025 | B12: =B10/B11 -> 2135.9409 | C12: =C10/C11 -> 2285.855 | D12: =D10/D11 -> 2348.981 | E12: =E10/E11 -> 2423.3545 | F12: =F10/F11 -> 2292.4 | G12: =G10/G11 -> 2420.3905 | H12: =H10/H11 -> 2299.1682 | I12: =I10/I11 -> 2331.7571 | ... N12: =N10/N11 -> 2330.3638

Sheet Variances Summary
A1: Current ME | B1: P09 | D1: Variances Summary by Business - FCAST10
A2: Next ME | B2: P10 | D2: TRAINING DATA ONLY - Zava Safety and all business names and numbers are fictitious. Layout mirrors a typical HFM / Cognos reporting pack.
C4: FCAST10
C5: Through Sep | F5: Rest of Year | I5: Full Year
B6: Favorable / (Unfavorable) | C6: Actual vs. FCAST09 | D6: Actual vs. Bud | E6: Actual vs. PY | F6: FCAST10 vs. FCAST09 | G6: FCAST10 vs. Bud | H6: FCAST10 vs. PY | I6: FCAST10 vs. FCAST09 | J6: FCAST10 vs. Bud | K6: FCAST10 vs. PY
B8: Sales
B9: Alder Gloves | C9: ='Alder'!BU28 -> 0 | D9: ='Alder'!BV28 -> 4321.5 | E9: ='Alder'!BW28 -> 9085.9 | F9: ='Alder'!BY28 -> -600 | G9: ='Alder'!BZ28 -> 890 | H9: ='Alder'!CA28 -> 2526.4 | I9: ='Alder'!CC28 -> -600 | J9: ='Alder'!CD28 -> 5211.5 | K9: ='Alder'!CE28 -> 11612.3
B10: Beacon Hi-Vis | C10: ='Beacon'!BU28 -> 150 | D10: ='Beacon'!BV28 -> 3250.8 | E10: ='Beacon'!BW28 -> 6179 | F10: ='Beacon'!BY28 -> 750 | G10: ='Beacon'!BZ28 -> 2417 | H10: ='Beacon'!CA28 -> 3639.3 | I10: ='Beacon'!CC28 -> 900 | J10: ='Beacon'!CD28 -> 5667.8 | K10: ='Beacon'!CE28 -> 9818.3
B11: Cobalt Eyewear | C11: ='Cobalt'!BU28 -> 30 | D11: ='Cobalt'!BV28 -> -114.6 | E11: ='Cobalt'!BW28 -> 1556.2 | F11: ='Cobalt'!BY28 -> 120 | G11: ='Cobalt'!BZ28 -> 5.5 | H11: ='Cobalt'!CA28 -> 598.8 | I11: ='Cobalt'!CC28 -> 150 | J11: ='Cobalt'!CD28 -> -109.1 | K11: ='Cobalt'!CE28 -> 2155
B12: Delta Welding Supply | C12: ='Delta'!BU28 -> 0 | D12: ='Delta'!BV28 -> -664 | E12: ='Delta'!BW28 -> 386.8 | F12: ='Delta'!BY28 -> 0 | G12: ='Delta'!BZ28 -> -260.6 | H12: ='Delta'!CA28 -> 8.4 | I12: ='Delta'!CC28 -> 0 | J12: ='Delta'!CD28 -> -924.6 | K12: ='Delta'!CE28 -> 395.2
B13: Ember Workwear | C13: ='Ember'!BU28 -> -260 | D13: ='Ember'!BV28 -> -1538.3 | E13: ='Ember'!BW28 -> -177 | F13: ='Ember'!BY28 -> -240 | G13: ='Ember'!BZ28 -> -978.4 | H13: ='Ember'!CA28 -> -640.3 | I13: ='Ember'!CC28 -> -500 | J13: ='Ember'!CD28 -> -2516.7 | K13: ='Ember'!CE28 -> -817.3
B14: Falcon Hand Protection | C14: ='Falcon'!BU28 -> 300 | D14: ='Falcon'!BV28 -> 5882 | E14: ='Falcon'!BW28 -> 9896.4 | F14: ='Falcon'!BY28 -> 900 | G14: ='Falcon'!BZ28 -> 3410.6 | H14: ='Falcon'!CA28 -> 4812.9 | I14: ='Falcon'!CC28 -> 1200 | J14: ='Falcon'!CD28 -> 9292.6 | K14: ='Falcon'!CE28 -> 14709.3
B15: Granite Gloves | C15: ='Granite'!BU28 -> -430 | D15: ='Granite'!BV28 -> -2792.4 | E15: ='Granite'!BW28 -> -1464.4 | F15: ='Granite'!BY28 -> -750 | G15: ='Granite'!BZ28 -> -1450.9 | H15: ='Granite'!CA28 -> -1011.2 | I15: ='Granite'!CC28 -> -1180 | J15: ='Granite'!CD28 -> -4243.3 | K15: ='Granite'!CE28 -> -2475.6
B16: Hollis Rainwear | C16: ='Hollis'!BU28 -> 1655 | D16: ='Hollis'!BV28 -> 2592.5 | E16: ='Hollis'!BW28 -> 6538.4 | F16: ='Hollis'!BY28 -> -1235 | G16: ='Hollis'!BZ28 -> -811.9 | H16: ='Hollis'!CA28 -> 308.9 | I16: ='Hollis'!CC28 -> 420 | J16: ='Hollis'!CD28 -> 1780.6 | K16: ='Hollis'!CE28 -> 6847.3
B17: Safety Region (regional office) | C17: ='SAFEREG'!BU28 -> 0 | D17: ='SAFEREG'!BV28 -> 0 | E17: ='SAFEREG'!BW28 -> 0 | F17: ='SAFEREG'!BY28 -> 0 | G17: ='SAFEREG'!BZ28 -> 0 | H17: ='SAFEREG'!CA28 -> 0 | I17: ='SAFEREG'!CC28 -> 0 | J17: ='SAFEREG'!CD28 -> 0 | K17: ='SAFEREG'!CE28 -> 0
B18: Total Zava Safety | C18: =SUM(C9:C17) -> 1445 | D18: =SUM(D9:D17) -> 10937.5 | E18: =SUM(E9:E17) -> 32001.3 | F18: =SUM(F9:F17) -> -1055 | G18: =SUM(G9:G17) -> 3221.3 | H18: =SUM(H9:H17) -> 10243.2 | I18: =SUM(I9:I17) -> 390 | J18: =SUM(J9:J17) -> 14158.8 | K18: =SUM(K9:K17) -> 42244.5
B20: Gross Margin
B21: Alder Gloves | C21: ='Alder'!BU29 -> -160 | D21: ='Alder'!BV29 -> -475.7 | E21: ='Alder'!BW29 -> 123.5 | F21: ='Alder'!BY29 -> -420 | G21: ='Alder'!BZ29 -> -1101 | H21: ='Alder'!CA29 -> -909.6 | I21: ='Alder'!CC29 -> -580 | J21: ='Alder'!CD29 -> -1576.7 | K21: ='Alder'!CE29 -> -786.1
B22: Beacon Hi-Vis | C22: ='Beacon'!BU29 -> 60 | D22: ='Beacon'!BV29 -> 2370.9 | E22: ='Beacon'!BW29 -> 3866.8 | F22: ='Beacon'!BY29 -> 290 | G22: ='Beacon'!BZ29 -> 1301.7 | H22: ='Beacon'!CA29 -> 1877.3 | I22: ='Beacon'!CC29 -> 350 | J22: ='Beacon'!CD29 -> 3672.6 | K22: ='Beacon'!CE29 -> 5744.1
B23: Cobalt Eyewear | C23: ='Cobalt'!BU29 -> -162 | D23: ='Cobalt'!BV29 -> -598.4 | E23: ='Cobalt'!BW29 -> 253.6 | F23: ='Cobalt'!BY29 -> -648 | G23: ='Cobalt'!BZ29 -> -833.5 | H23: ='Cobalt'!CA29 -> -575.4 | I23: ='Cobalt'!CC29 -> -810 | J23: ='Cobalt'!CD29 -> -1431.9 | K23: ='Cobalt'!CE29 -> -321.8
B24: Delta Welding Supply | C24: ='Delta'!BU29 -> 0 | D24: ='Delta'!BV29 -> -209.7 | E24: ='Delta'!BW29 -> 72.2 | F24: ='Delta'!BY29 -> 0 | G24: ='Delta'!BZ29 -> -94.7 | H24: ='Delta'!CA29 -> -5.2 | I24: ='Delta'!CC29 -> 0 | J24: ='Delta'!CD29 -> -304.4 | K24: ='Delta'!CE29 -> 67
B25: Ember Workwear | C25: ='Ember'!BU29 -> -83 | D25: ='Ember'!BV29 -> -633 | E25: ='Ember'!BW29 -> -140.5 | F25: ='Ember'!BY29 -> -77 | G25: ='Ember'!BZ29 -> -363.5 | H25: ='Ember'!CA29 -> -238.1 | I25: ='Ember'!CC29 -> -160 | J25: ='Ember'!CD29 -> -996.5 | K25: ='Ember'!CE29 -> -378.6
B26: Falcon Hand Protection | C26: ='Falcon'!BU29 -> 120 | D26: ='Falcon'!BV29 -> 3096.1 | E26: ='Falcon'!BW29 -> 4787.3 | F26: ='Falcon'!BY29 -> 360 | G26: ='Falcon'!BZ29 -> 1607.6 | H26: ='Falcon'!CA29 -> 2147.9 | I26: ='Falcon'!CC29 -> 480 | J26: ='Falcon'!CD29 -> 4703.7 | K26: ='Falcon'!CE29 -> 6935.2
B27: Granite Gloves | C27: ='Granite'!BU29 -> -265 | D27: ='Granite'!BV29 -> -1639.9 | E27: ='Granite'!BW29 -> -1517.3 | F27: ='Granite'!BY29 -> -260 | G27: ='Granite'!BZ29 -> -712.2 | H27: ='Granite'!CA29 -> -668.9 | I27: ='Granite'!CC29 -> -525 | J27: ='Granite'!CD29 -> -2352.1 | K27: ='Granite'!CE29 -> -2186.2
B28: Hollis Rainwear | C28: ='Hollis'!BU29 -> 242 | D28: ='Hollis'!BV29 -> 207.5 | E28: ='Hollis'!BW29 -> 1310 | F28: ='Hollis'!BY29 -> 6 | G28: ='Hollis'!BZ29 -> 50 | H28: ='Hollis'!CA29 -> 357.9 | I28: ='Hollis'!CC29 -> 248 | J28: ='Hollis'!CD29 -> 257.5 | K28: ='Hollis'!CE29 -> 1667.9
B29: Safety Region (regional office) | C29: ='SAFEREG'!BU29 -> 0 | D29: ='SAFEREG'!BV29 -> 0 | E29: ='SAFEREG'!BW29 -> 0 | F29: ='SAFEREG'!BY29 -> 0 | G29: ='SAFEREG'!BZ29 -> 0 | H29: ='SAFEREG'!CA29 -> 0 | I29: ='SAFEREG'!CC29 -> 0 | J29: ='SAFEREG'!CD29 -> 0 | K29: ='SAFEREG'!CE29 -> 0
B30: Total Zava Safety | C30: =SUM(C21:C29) -> -248 | D30: =SUM(D21:D29) -> 2117.8 | E30: =SUM(E21:E29) -> 8755.6 | F30: =SUM(F21:F29) -> -749 | G30: =SUM(G21:G29) -> -145.6 | H30: =SUM(H21:H29) -> 1985.9 | I30: =SUM(I21:I29) -> -997 | J30: =SUM(J21:J29) -> 1972.2 | K30: =SUM(K21:K29) -> 10741.5
B32: Op Costs
B33: Alder Gloves | C33: ='Alder'!BU30 -> 240 | D33: ='Alder'!BV30 -> -174.7 | E33: ='Alder'!BW30 -> -899.6 | F33: ='Alder'!BY30 -> 60 | G33: ='Alder'!BZ30 -> -77.2 | H33: ='Alder'!CA30 -> -330.8 | I33: ='Alder'!CC30 -> 300 | J33: ='Alder'!CD30 -> -251.9 | K33: ='Alder'!CE30 -> -1230.4
B34: Beacon Hi-Vis | C34: ='Beacon'!BU30 -> -76 | D34: ='Beacon'!BV30 -> -434.8 | E34: ='Beacon'!BW30 -> -863.9 | F34: ='Beacon'!BY30 -> -30 | G34: ='Beacon'!BZ30 -> -233 | H34: ='Beacon'!CA30 -> -364.9 | I34: ='Beacon'!CC30 -> -106 | J34: ='Beacon'!CD30 -> -667.8 | K34: ='Beacon'!CE30 -> -1228.8
B35: Cobalt Eyewear | C35: ='Cobalt'!BU30 -> 6 | D35: ='Cobalt'!BV30 -> -85.3 | E35: ='Cobalt'!BW30 -> -285 | F35: ='Cobalt'!BY30 -> -36 | G35: ='Cobalt'!BZ30 -> -30 | H35: ='Cobalt'!CA30 -> -101.5 | I35: ='Cobalt'!CC30 -> -30 | J35: ='Cobalt'!CD30 -> -115.3 | K35: ='Cobalt'!CE30 -> -386.5
B36: Delta Welding Supply | C36: ='Delta'!BU30 -> 0 | D36: ='Delta'!BV30 -> 78.5 | E36: ='Delta'!BW30 -> -53.8 | F36: ='Delta'!BY30 -> 0 | G36: ='Delta'!BZ30 -> 33.1 | H36: ='Delta'!CA30 -> -9.8 | I36: ='Delta'!CC30 -> 0 | J36: ='Delta'!CD30 -> 111.6 | K36: ='Delta'!CE30 -> -63.6
B37: Ember Workwear | C37: ='Ember'!BU30 -> 10 | D37: ='Ember'!BV30 -> 173.1 | E37: ='Ember'!BW30 -> 13.3 | F37: ='Ember'!BY30 -> 30 | G37: ='Ember'!BZ30 -> 105.3 | H37: ='Ember'!CA30 -> 48 | I37: ='Ember'!CC30 -> 40 | J37: ='Ember'!CD30 -> 278.4 | K37: ='Ember'!CE30 -> 61.3
B38: Falcon Hand Protection | C38: ='Falcon'!BU30 -> -110 | D38: ='Falcon'!BV30 -> -662.9 | E38: ='Falcon'!BW30 -> -1166.4 | F38: ='Falcon'!BY30 -> -40 | G38: ='Falcon'!BZ30 -> -283.2 | H38: ='Falcon'!CA30 -> -466.9 | I38: ='Falcon'!CC30 -> -150 | J38: ='Falcon'!CD30 -> -946.1 | K38: ='Falcon'!CE30 -> -1633.3
B39: Granite Gloves | C39: ='Granite'!BU30 -> 42 | D39: ='Granite'!BV30 -> 254.5 | E39: ='Granite'!BW30 -> 48.4 | F39: ='Granite'!BY30 -> 132 | G39: ='Granite'!BZ30 -> 219.7 | H39: ='Granite'!CA30 -> 161.4 | I39: ='Granite'!CC30 -> 174 | J39: ='Granite'!CD30 -> 474.2 | K39: ='Granite'!CE30 -> 209.8
B40: Hollis Rainwear | C40: ='Hollis'!BU30 -> 39 | D40: ='Hollis'!BV30 -> 215.7 | E40: ='Hollis'!BW30 -> -267.2 | F40: ='Hollis'!BY30 -> 507 | G40: ='Hollis'!BZ30 -> 635.3 | H40: ='Hollis'!CA30 -> 463.6 | I40: ='Hollis'!CC30 -> 546 | J40: ='Hollis'!CD30 -> 851 | K40: ='Hollis'!CE30 -> 196.4
B41: Safety Region (regional office) | C41: ='SAFEREG'!BU30 -> 0 | D41: ='SAFEREG'!BV30 -> 1.8 | E41: ='SAFEREG'!BW30 -> -94.8 | F41: ='SAFEREG'!BY30 -> 0 | G41: ='SAFEREG'!BZ30 -> 2.8 | H41: ='SAFEREG'!CA30 -> -36.8 | I41: ='SAFEREG'!CC30 -> 0 | J41: ='SAFEREG'!CD30 -> 4.6 | K41: ='SAFEREG'!CE30 -> -131.6
B42: Total Zava Safety | C42: =SUM(C33:C41) -> 151 | D42: =SUM(D33:D41) -> -634.1 | E42: =SUM(E33:E41) -> -3569 | F42: =SUM(F33:F41) -> 623 | G42: =SUM(G33:G41) -> 372.8 | H42: =SUM(H33:H41) -> -637.7 | I42: =SUM(I33:I41) -> 774 | J42: =SUM(J33:J41) -> -261.3 | K42: =SUM(K33:K41) -> -4206.7
B44: PBITA
B45: Alder Gloves | C45: ='Alder'!BU31 -> 80 | D45: ='Alder'!BV31 -> -650.4 | E45: ='Alder'!BW31 -> -776.1 | F45: ='Alder'!BY31 -> -360 | G45: ='Alder'!BZ31 -> -1178.2 | H45: ='Alder'!CA31 -> -1240.4 | I45: ='Alder'!CC31 -> -280 | J45: ='Alder'!CD31 -> -1828.6 | K45: ='Alder'!CE31 -> -2016.5
...

Sheet Exec Smry Safety
A1: Index | B1: Division | C1: Zava Safety
D2: TRAINING DATA ONLY - Zava Safety and all business names and numbers are fictitious. Layout mirrors a typical HFM / Cognos reporting pack.
F3: FCAST09 | I3: FCAST10 vs. FCAST09 | O3: FCAST10
F4: FY26 | I4: September | L4: Rest of Year | O4: FY26 | R4: Check vs. sum of businesses
D7: Sales | F7: =Safety!O28 -> 633766.9 | I7: =Safety!BO28-Safety!K28 -> 1445 | L7: =SUM(Safety!BP28:BR28)-SUM(Safety!L28:N28) -> -1055 | O7: =Safety!BS28 -> 634156.9 | R7: =ROUND(O7-('Alder'!BS28+'Beacon'!BS28+'Cobalt'!BS28+'Delta'!BS28+'Ember'!BS28+'Falcon'!BS28+'Granite'!BS28+'Hollis'!BS28+'SAFEREG'!BS28),1) -> 0
D9: Gross Margin | F9: =Safety!O29 -> 197718.7 | I9: =Safety!BO29-Safety!K29 -> -85.92 | L9: =SUM(Safety!BP29:BR29)-SUM(Safety!L29:N29) -> -100.76 | O9: =Safety!BS29 -> 197532.02 | R9: =ROUND(O9-('Alder'!BS29+'Beacon'!BS29+'Cobalt'!BS29+'Delta'!BS29+'Ember'!BS29+'Falcon'!BS29+'Granite'!BS29+'Hollis'!BS29+'SAFEREG'!BS29),1) -> 810.3
D10: % / Leverage | F10: =IFERROR(F9/F7,0) -> 0.31197385 | I10: =IFERROR(I9/I7,0) -> -0.059460208 | L10: =IFERROR(L9/L7,0) -> 0.095507109 | O10: =IFERROR(O9/O7,0) -> 0.31148761
D12: Op Costs | F12: =Safety!O30 -> -135761.7 | I12: =Safety!BO30-Safety!K30 -> 151 | L12: =SUM(Safety!BP30:BR30)-SUM(Safety!L30:N30) -> 623 | O12: =Safety!BS30 -> -134987.7 | R12: =ROUND(O12-('Alder'!BS30+'Beacon'!BS30+'Cobalt'!BS30+'Delta'!BS30+'Ember'!BS30+'Falcon'!BS30+'Granite'!BS30+'Hollis'!BS30+'SAFEREG'!BS30),1) -> 0
D13: % / Leverage | F13: =IFERROR(F12/F7,0) -> -0.21421393 | I13: =IFERROR(I12/I7,0) -> 0.10449827 | L13: =IFERROR(L12/L7,0) -> -0.59052133 | O13: =IFERROR(O12/O7,0) -> -0.21286168
D15: PBITA | F15: =Safety!O31 -> 61957 | I15: =Safety!BO31-Safety!K31 -> 65.08 | L15: =SUM(Safety!BP31:BR31)-SUM(Safety!L31:N31) -> 522.24 | O15: =Safety!BS31 -> 62544.32 | R15: =ROUND(O15-('Alder'!BS31+'Beacon'!BS31+'Cobalt'!BS31+'Delta'!BS31+'Ember'!BS31+'Falcon'!BS31+'Granite'!BS31+'Hollis'!BS31+'SAFEREG'!BS31),1) -> 810.3
D16: % / Leverage | F16: =IFERROR(F15/F7,0) -> 0.097759918 | I16: =IFERROR(I15/I7,0) -> 0.045038062 | L16: =IFERROR(L15/L7,0) -> -0.49501422 | O16: =IFERROR(O15/O7,0) -> 0.098625939
F18: Budget | I18: FCAST10 vs. Budget | L18: Actual | O18: FCAST10 vs. FY25
F19: FY26 | L19: FY25
C22: Sales | F22: =Safety!O51 -> 619998.1 | I22: =O7-F22 -> 14158.8 | L22: =Safety!O64 -> 591912.4 | O22: =O7-L22 -> 42244.5
C24: Gross Margin | F24: =Safety!O52 -> 194749.5 | I24: =O9-F24 -> 2782.52 | L24: =Safety!O65 -> 185980.2 | O24: =O9-L24 -> 11551.82
C25: % | F25: =IFERROR(F24/F22,0) -> 0.31411306 | L25: =IFERROR(L24/L22,0) -> 0.31420224
C27: Op Costs | F27: =Safety!O53 -> -134726.4 | I27: =O12-F27 -> -261.3 | L27: =Safety!O66 -> -130781 | O27: =O12-L27 -> -4206.7
C28: % | F28: =IFERROR(F27/F22,0) -> -0.21730131 | L28: =IFERROR(L27/L22,0) -> -0.22094655
C30: PBITA | F30: =Safety!O54 -> 60023.1 | I30: =O15-F30 -> 2521.22 | L30: =Safety!O67 -> 55199.2 | O30: =O15-L30 -> 7345.12
C31: % | F31: =IFERROR(F30/F22,0) -> 0.096811748 | L31: =IFERROR(L30/L22,0) -> 0.093255691

Sheet Safety-Var
A1: Current ME | B1: P09 | D1: Zava Safety - Consolidated
A2: Next ME | B2: P10 | D2: TRAINING DATA ONLY - Zava Safety and all business names and numbers are fictitious. Layout mirrors a typical HFM / Cognos reporting pack.
C4: FCAST10
C5: Through Sep | F5: Rest of Year | I5: Full Year
B6: Favorable / (Unfavorable) | C6: Actual vs. FCAST09 | D6: Actual vs. Bud | E6: Actual vs. PY | F6: FCAST10 vs. FCAST09 | G6: FCAST10 vs. Bud | H6: FCAST10 vs. PY | I6: FCAST10 vs. FCAST09 | J6: FCAST10 vs. Bud | K6: FCAST10 vs. PY
B8: Sales | C8: ='Safety'!BU28 -> 1445 | D8: ='Safety'!BV28 -> 10937.5 | E8: ='Safety'!BW28 -> 32001.3 | F8: ='Safety'!BY28 -> -1055 | G8: ='Safety'!BZ28 -> 3221.3 | H8: ='Safety'!CA28 -> 10243.2 | I8: ='Safety'!CC28 -> 390 | J8: ='Safety'!CD28 -> 14158.8 | K8: ='Safety'!CE28 -> 42244.5
B10: Gross Margin | C10: ='Safety'!BU29 -> -85.92 | D10: ='Safety'!BV29 -> 2279.88 | E10: ='Safety'!BW29 -> 8917.68 | F10: ='Safety'!BY29 -> -100.76 | G10: ='Safety'!BZ29 -> 502.64 | H10: ='Safety'!CA29 -> 2634.14 | I10: ='Safety'!CC29 -> -186.68 | J10: ='Safety'!CD29 -> 2782.52 | K10: ='Safety'!CE29 -> 11551.82
B12: Op Costs | C12: ='Safety'!BU30 -> 151 | D12: ='Safety'!BV30 -> -634.1 | E12: ='Safety'!BW30 -> -3569 | F12: ='Safety'!BY30 -> 623 | G12: ='Safety'!BZ30 -> 372.8 | H12: ='Safety'!CA30 -> -637.7 | I12: ='Safety'!CC30 -> 774 | J12: ='Safety'!CD30 -> -261.3 | K12: ='Safety'!CE30 -> -4206.7
B14: PBITA | C14: ='Safety'!BU31 -> 65.08 | D14: ='Safety'!BV31 -> 1645.78 | E14: ='Safety'!BW31 -> 5348.68 | F14: ='Safety'!BY31 -> 522.24 | G14: ='Safety'!BZ31 -> 875.44 | H14: ='Safety'!CA31 -> 1996.44 | I14: ='Safety'!CC31 -> 587.32 | J14: ='Safety'!CD31 -> 2521.22 | K14: ='Safety'!CE31 -> 7345.12
B17: Commentary (business controller):

Sheet Safety-Adj
A1: Index | C1: 46053 | D1: 46081 | E1: 46112 | F1: 46142 | G1: 46173 | H1: 46203 | I1: 46234 | J1: 46265 | K1: 46295 | L1: 46326 | M1: 46356 | N1: 46387
B2: Section 1: Adjustments tied to individual events (i.e., new customer, modified sales contract, new/lost customer):
B3: TRAINING DATA ONLY - Zava Safety and all business names and numbers are fictitious. Layout mirrors a typical HFM / Cognos reporting pack.
C4: January | D4: February | E4: March | F4: April | G4: May | H4: June | I4: July | J4: August | K4: September | L4: October | M4: November | N4: December | O4: Total Adjustments | Q4: YTG
B5: Sales
B6: Alder Gloves | C6: ='Alder-Adj'!C$14 -> 0 | D6: ='Alder-Adj'!D$14 -> 0 | E6: ='Alder-Adj'!E$14 -> 0 | F6: ='Alder-Adj'!F$14 -> 0 | G6: ='Alder-Adj'!G$14 -> 0 | H6: ='Alder-Adj'!H$14 -> 0 | I6: ='Alder-Adj'!I$14 -> 0 | J6: ='Alder-Adj'!J$14 -> 0 | ... N6: ='Alder-Adj'!N$14 -> -200 | O6: =SUM(C6:N6) -> -600 | Q6: =SUM(L6:N6) -> -600
B7: Beacon Hi-Vis | C7: ='Beacon-Adj'!C$14 -> 0 | D7: ='Beacon-Adj'!D$14 -> 0 | E7: ='Beacon-Adj'!E$14 -> 0 | F7: ='Beacon-Adj'!F$14 -> 0 | G7: ='Beacon-Adj'!G$14 -> 0 | H7: ='Beacon-Adj'!H$14 -> 0 | I7: ='Beacon-Adj'!I$14 -> 0 | J7: ='Beacon-Adj'!J$14 -> 0 | ... N7: ='Beacon-Adj'!N$14 -> 200 | O7: =SUM(C7:N7) -> 900 | Q7: =SUM(L7:N7) -> 750
B8: Cobalt Eyewear | C8: ='Cobalt-Adj'!C$14 -> 0 | D8: ='Cobalt-Adj'!D$14 -> 0 | E8: ='Cobalt-Adj'!E$14 -> 0 | F8: ='Cobalt-Adj'!F$14 -> 0 | G8: ='Cobalt-Adj'!G$14 -> 0 | H8: ='Cobalt-Adj'!H$14 -> 0 | I8: ='Cobalt-Adj'!I$14 -> 0 | J8: ='Cobalt-Adj'!J$14 -> 0 | ... N8: ='Cobalt-Adj'!N$14 -> 40 | O8: =SUM(C8:N8) -> 150 | Q8: =SUM(L8:N8) -> 120
B9: Delta Welding Supply | C9: ='Delta-Adj'!C$14 -> 0 | D9: ='Delta-Adj'!D$14 -> 0 | E9: ='Delta-Adj'!E$14 -> 0 | F9: ='Delta-Adj'!F$14 -> 0 | G9: ='Delta-Adj'!G$14 -> 0 | H9: ='Delta-Adj'!H$14 -> 0 | I9: ='Delta-Adj'!I$14 -> 0 | J9: ='Delta-Adj'!J$14 -> 0 | ... N9: ='Delta-Adj'!N$14 -> 0 | O9: =SUM(C9:N9) -> 0 | Q9: =SUM(L9:N9) -> 0
B10: Ember Workwear | C10: ='Ember-Adj'!C$14 -> 0 | D10: ='Ember-Adj'!D$14 -> 0 | E10: ='Ember-Adj'!E$14 -> 0 | F10: ='Ember-Adj'!F$14 -> 0 | G10: ='Ember-Adj'!G$14 -> 0 | H10: ='Ember-Adj'!H$14 -> 0 | I10: ='Ember-Adj'!I$14 -> 0 | J10: ='Ember-Adj'!J$14 -> 0 | ... N10: ='Ember-Adj'!N$14 -> 0 | O10: =SUM(C10:N10) -> -500 | Q10: =SUM(L10:N10) -> -240
B11: Falcon Hand Protection | C11: ='Falcon-Adj'!C$14 -> 0 | D11: ='Falcon-Adj'!D$14 -> 0 | E11: ='Falcon-Adj'!E$14 -> 0 | F11: ='Falcon-Adj'!F$14 -> 0 | G11: ='Falcon-Adj'!G$14 -> 0 | H11: ='Falcon-Adj'!H$14 -> 0 | I11: ='Falcon-Adj'!I$14 -> 0 | J11: ='Falcon-Adj'!J$14 -> 0 | ... N11: ='Falcon-Adj'!N$14 -> 300 | O11: =SUM(C11:N11) -> 1200 | Q11: =SUM(L11:N11) -> 900
B12: Granite Gloves | C12: ='Granite-Adj'!C$14 -> 0 | D12: ='Granite-Adj'!D$14 -> 0 | E12: ='Granite-Adj'!E$14 -> 0 | F12: ='Granite-Adj'!F$14 -> 0 | G12: ='Granite-Adj'!G$14 -> 0 | H12: ='Granite-Adj'!H$14 -> 0 | I12: ='Granite-Adj'!I$14 -> 0 | J12: ='Granite-Adj'!J$14 -> 0 | ... N12: ='Granite-Adj'!N$14 -> -300 | O12: =SUM(C12:N12) -> -1180 | Q12: =SUM(L12:N12) -> -750
B13: Hollis Rainwear | C13: ='Hollis-Adj'!C$14 -> 0 | D13: ='Hollis-Adj'!D$14 -> 0 | E13: ='Hollis-Adj'!E$14 -> 0 | F13: ='Hollis-Adj'!F$14 -> 0 | G13: ='Hollis-Adj'!G$14 -> 0 | H13: ='Hollis-Adj'!H$14 -> 0 | I13: ='Hollis-Adj'!I$14 -> 0 | J13: ='Hollis-Adj'!J$14 -> 0 | ... N13: ='Hollis-Adj'!N$14 -> 300 | O13: =SUM(C13:N13) -> 600 | Q13: =SUM(L13:N13) -> -1100
B14: SAFEREG | C14: ='SAFEREG-Adj'!C$14 -> 0 | D14: ='SAFEREG-Adj'!D$14 -> 0 | E14: ='SAFEREG-Adj'!E$14 -> 0 | F14: ='SAFEREG-Adj'!F$14 -> 0 | G14: ='SAFEREG-Adj'!G$14 -> 0 | H14: ='SAFEREG-Adj'!H$14 -> 0 | I14: ='SAFEREG-Adj'!I$14 -> 0 | J14: ='SAFEREG-Adj'!J$14 -> 0 | ... N14: ='SAFEREG-Adj'!N$14 -> 0 | O14: =SUM(C14:N14) -> 0 | Q14: =SUM(L14:N14) -> 0
B15: Total Sales | C15: =SUM(C6:C14) -> 0 | D15: =SUM(D6:D14) -> 0 | E15: =SUM(E6:E14) -> 0 | F15: =SUM(F6:F14) -> 0 | G15: =SUM(G6:G14) -> 0 | H15: =SUM(H6:H14) -> 0 | I15: =SUM(I6:I14) -> 0 | J15: =SUM(J6:J14) -> 0 | ... O15: =SUM(O6:O14) -> 570 | Q15: =SUM(L15:N15) -> -920
B17: Gross Margin (%)
B18: Alder Gloves | C18: =IFERROR(C30/C6,"-") -> - | D18: =IFERROR(D30/D6,"-") -> - | E18: =IFERROR(E30/E6,"-") -> - | F18: =IFERROR(F30/F6,"-") -> - | G18: =IFERROR(G30/G6,"-") -> - | H18: =IFERROR(H30/H6,"-") -> - | I18: =IFERROR(I30/I6,"-") -> - | J18: =IFERROR(J30/J6,"-") -> - | ... O18: =IFERROR(O30/O6,"-") -> 0.96666667
B19: Beacon Hi-Vis | C19: =IFERROR(C31/C7,"-") -> - | D19: =IFERROR(D31/D7,"-") -> - | E19: =IFERROR(E31/E7,"-") -> - | F19: =IFERROR(F31/F7,"-") -> - | G19: =IFERROR(G31/G7,"-") -> - | H19: =IFERROR(H31/H7,"-") -> - | I19: =IFERROR(I31/I7,"-") -> - | J19: =IFERROR(J31/J7,"-") -> - | ... O19: =IFERROR(O31/O7,"-") -> 0.38888889
B20: Cobalt Eyewear | C20: =IFERROR(C32/C8,"-") -> - | D20: =IFERROR(D32/D8,"-") -> - | E20: =IFERROR(E32/E8,"-") -> - | F20: =IFERROR(F32/F8,"-") -> - | G20: =IFERROR(G32/G8,"-") -> - | H20: =IFERROR(H32/H8,"-") -> - | I20: =IFERROR(I32/I8,"-") -> - | J20: =IFERROR(J32/J8,"-") -> - | ... O20: =IFERROR(O32/O8,"-") -> 0.0021333333
B21: Delta Welding Supply | C21: =IFERROR(C33/C9,"-") -> - | D21: =IFERROR(D33/D9,"-") -> - | E21: =IFERROR(E33/E9,"-") -> - | F21: =IFERROR(F33/F9,"-") -> - | G21: =IFERROR(G33/G9,"-") -> - | H21: =IFERROR(H33/H9,"-") -> - | I21: =IFERROR(I33/I9,"-") -> - | J21: =IFERROR(J33/J9,"-") -> - | ... O21: =IFERROR(O33/O9,"-") -> -
B22: Ember Workwear | C22: =IFERROR(C34/C10,"-") -> - | D22: =IFERROR(D34/D10,"-") -> - | E22: =IFERROR(E34/E10,"-") -> - | F22: =IFERROR(F34/F10,"-") -> - | G22: =IFERROR(G34/G10,"-") -> - | H22: =IFERROR(H34/H10,"-") -> - | I22: =IFERROR(I34/I10,"-") -> - | J22: =IFERROR(J34/J10,"-") -> - | ... O22: =IFERROR(O34/O10,"-") -> 0.32
B23: Falcon Hand Protection | C23: =IFERROR(C35/C11,"-") -> - | D23: =IFERROR(D35/D11,"-") -> - | E23: =IFERROR(E35/E11,"-") -> - | F23: =IFERROR(F35/F11,"-") -> - | G23: =IFERROR(G35/G11,"-") -> - | H23: =IFERROR(H35/H11,"-") -> - | I23: =IFERROR(I35/I11,"-") -> - | J23: =IFERROR(J35/J11,"-") -> - | ... O23: =IFERROR(O35/O11,"-") -> 0.4
B24: Granite Gloves | C24: =IFERROR(C36/C12,"-") -> - | D24: =IFERROR(D36/D12,"-") -> - | E24: =IFERROR(E36/E12,"-") -> - | F24: =IFERROR(F36/F12,"-") -> - | G24: =IFERROR(G36/G12,"-") -> - | H24: =IFERROR(H36/H12,"-") -> - | I24: =IFERROR(I36/I12,"-") -> - | J24: =IFERROR(J36/J12,"-") -> - | ... O24: =IFERROR(O36/O12,"-") -> 0.44491525
B25: Hollis Rainwear | C25: =IFERROR(C37/C13,"-") -> - | D25: =IFERROR(D37/D13,"-") -> - | E25: =IFERROR(E37/E13,"-") -> - | F25: =IFERROR(F37/F13,"-") -> - | G25: =IFERROR(G37/G13,"-") -> - | H25: =IFERROR(H37/H13,"-") -> - | I25: =IFERROR(I37/I13,"-") -> - | J25: =IFERROR(J37/J13,"-") -> - | ... O25: =IFERROR(O37/O13,"-") -> 0.5
B26: SAFEREG | C26: =IFERROR(C38/C14,"-") -> - | D26: =IFERROR(D38/D14,"-") -> - | E26: =IFERROR(E38/E14,"-") -> - | F26: =IFERROR(F38/F14,"-") -> - | G26: =IFERROR(G38/G14,"-") -> - | H26: =IFERROR(H38/H14,"-") -> - | I26: =IFERROR(I38/I14,"-") -> - | J26: =IFERROR(J38/J14,"-") -> - | ... O26: =IFERROR(O38/O14,"-") -> -
B27: Total Gross Margin (%) | C27: =IFERROR(C39/C15,"-") -> - | D27: =IFERROR(D39/D15,"-") -> - | E27: =IFERROR(E39/E15,"-") -> - | F27: =IFERROR(F39/F15,"-") -> - | G27: =IFERROR(G39/G15,"-") -> - | H27: =IFERROR(H39/H15,"-") -> - | I27: =IFERROR(I39/I15,"-") -> - | J27: =IFERROR(J39/J15,"-") -> - | ... O27: =IFERROR(O39/O15,"-") -> -0.2362807
B29: Gross Margin ($)
B30: Alder Gloves | C30: ='Alder-Adj'!C$36 -> 0 | D30: ='Alder-Adj'!D$36 -> 0 | E30: ='Alder-Adj'!E$36 -> 0 | F30: ='Alder-Adj'!F$36 -> 0 | G30: ='Alder-Adj'!G$36 -> 0 | H30: ='Alder-Adj'!H$36 -> 0 | I30: ='Alder-Adj'!I$36 -> 0 | J30: ='Alder-Adj'!J$36 -> 0 | ... N30: ='Alder-Adj'!N$36 -> -140 | O30: =SUM(C30:N30) -> -580 | Q30: =SUM(L30:N30) -> -420
B31: Beacon Hi-Vis | C31: ='Beacon-Adj'!C$36 -> 0 | D31: ='Beacon-Adj'!D$36 -> 0 | E31: ='Beacon-Adj'!E$36 -> 0 | F31: ='Beacon-Adj'!F$36 -> 0 | G31: ='Beacon-Adj'!G$36 -> 0 | H31: ='Beacon-Adj'!H$36 -> 0 | I31: ='Beacon-Adj'!I$36 -> 0 | J31: ='Beacon-Adj'!J$36 -> 0 | ... N31: ='Beacon-Adj'!N$36 -> 80 | O31: =SUM(C31:N31) -> 350 | Q31: =SUM(L31:N31) -> 290
B32: Cobalt Eyewear | C32: ='Cobalt-Adj'!C$39 -> 0 | D32: ='Cobalt-Adj'!D$39 -> 0 | E32: ='Cobalt-Adj'!E$39 -> 0 | H32: ='Cobalt-Adj'!H$39 -> 0 | I32: ='Cobalt-Adj'!I$39 -> 0 | J32: ='Cobalt-Adj'!J$39 -> 0 | K32: ='Cobalt-Adj'!K$39 -> 0.08 | L32: ='Cobalt-Adj'!L$39 -> 0.08 | M32: ='Cobalt-Adj'!M$39 -> 0.08 | N32: ='Cobalt-Adj'!N$39 -> 0.08 | O32: =SUM(C32:N32) -> 0.32 | Q32: =SUM(L32:N32) -> 0.24
B33: Delta Welding Supply | C33: ='Delta-Adj'!C$36 -> 0 | D33: ='Delta-Adj'!D$36 -> 0 | E33: ='Delta-Adj'!E$36 -> 0 | F33: ='Delta-Adj'!F$36 -> 0 | G33: ='Delta-Adj'!G$36 -> 0 | H33: ='Delta-Adj'!H$36 -> 0 | I33: ='Delta-Adj'!I$36 -> 0 | J33: ='Delta-Adj'!J$36 -> 0 | ... N33: ='Delta-Adj'!N$36 -> 0 | O33: =SUM(C33:N33) -> 0 | Q33: =SUM(L33:N33) -> 0
B34: Ember Workwear | C34: ='Ember-Adj'!C$36 -> 0 | D34: ='Ember-Adj'!D$36 -> 0 | E34: ='Ember-Adj'!E$36 -> 0 | F34: ='Ember-Adj'!F$36 -> 0 | G34: ='Ember-Adj'!G$36 -> 0 | H34: ='Ember-Adj'!H$36 -> 0 | I34: ='Ember-Adj'!I$36 -> 0 | J34: ='Ember-Adj'!J$36 -> 0 | ... N34: ='Ember-Adj'!N$36 -> 0 | O34: =SUM(C34:N34) -> -160 | Q34: =SUM(L34:N34) -> -77
B35: Falcon Hand Protection | C35: ='Falcon-Adj'!C$36 -> 0 | D35: ='Falcon-Adj'!D$36 -> 0 | E35: ='Falcon-Adj'!E$36 -> 0 | F35: ='Falcon-Adj'!F$36 -> 0 | G35: ='Falcon-Adj'!G$36 -> 0 | H35: ='Falcon-Adj'!H$36 -> 0 | I35: ='Falcon-Adj'!I$36 -> 0 | J35: ='Falcon-Adj'!J$36 -> 0 | ... N35: ='Falcon-Adj'!N$36 -> 120 | O35: =SUM(C35:N35) -> 480 | Q35: =SUM(L35:N35) -> 360
B36: Granite Gloves | C36: ='Granite-Adj'!C$36 -> 0 | D36: ='Granite-Adj'!D$36 -> 0 | E36: ='Granite-Adj'!E$36 -> 0 | F36: ='Granite-Adj'!F$36 -> 0 | G36: ='Granite-Adj'!G$36 -> 0 | H36: ='Granite-Adj'!H$36 -> 0 | I36: ='Granite-Adj'!I$36 -> 0 | J36: ='Granite-Adj'!J$36 -> 0 | ... N36: ='Granite-Adj'!N$36 -> -31 | O36: =SUM(C36:N36) -> -525 | Q36: =SUM(L36:N36) -> -260
B37: Hollis Rainwear | C37: ='Hollis-Adj'!C$36 -> 0 | D37: ='Hollis-Adj'!D$36 -> 0 | E37: ='Hollis-Adj'!E$36 -> 0 | F37: ='Hollis-Adj'!F$36 -> 0 | G37: ='Hollis-Adj'!G$36 -> 0 | H37: ='Hollis-Adj'!H$36 -> 0 | I37: ='Hollis-Adj'!I$36 -> 0 | J37: ='Hollis-Adj'!J$36 -> 0 | ... N37: ='Hollis-Adj'!N$36 -> 210 | O37: =SUM(C37:N37) -> 300 | Q37: =SUM(L37:N37) -> 45
B38: SAFEREG | C38: ='SAFEREG-Adj'!C$36 -> 0 | D38: ='SAFEREG-Adj'!D$36 -> 0 | E38: ='SAFEREG-Adj'!E$36 -> 0 | F38: ='SAFEREG-Adj'!F$36 -> 0 | G38: ='SAFEREG-Adj'!G$36 -> 0 | H38: ='SAFEREG-Adj'!H$36 -> 0 | I38: ='SAFEREG-Adj'!I$36 -> 0 | J38: ='SAFEREG-Adj'!J$36 -> 0 | ... N38: ='SAFEREG-Adj'!N$36 -> 0 | O38: =SUM(C38:N38) -> 0 | Q38: =SUM(L38:N38) -> 0
B39: Total Gross Margin ($) | C39: =SUM(C30:C38) -> 0 | D39: =SUM(D30:D38) -> 0 | E39: =SUM(E30:E38) -> 0 | F39: =SUM(F30:F38) -> 0 | G39: =SUM(G30:G38) -> 0 | H39: =SUM(H30:H38) -> 0 | I39: =SUM(I30:I38) -> 0 | J39: =SUM(J30:J38) -> 0 | ... O39: =SUM(O30:O38) -> -134.68 | Q39: =SUM(L39:N39) -> -61.76
B41: Op Costs (%)
B42: Alder Gloves | C42: =IFERROR(C54/C6,"-") -> - | D42: =IFERROR(D54/D6,"-") -> - | E42: =IFERROR(E54/E6,"-") -> - | F42: =IFERROR(F54/F6,"-") -> - | G42: =IFERROR(G54/G6,"-") -> - | H42: =IFERROR(H54/H6,"-") -> - | I42: =IFERROR(I54/I6,"-") -> - | J42: =IFERROR(J54/J6,"-") -> - | ... O42: =IFERROR(O54/O6,"-") -> 0.5
B43: Beacon Hi-Vis | C43: =IFERROR(C55/C7,"-") -> - | D43: =IFERROR(D55/D7,"-") -> - | E43: =IFERROR(E55/E7,"-") -> - | F43: =IFERROR(F55/F7,"-") -> - | G43: =IFERROR(G55/G7,"-") -> - | H43: =IFERROR(H55/H7,"-") -> - | I43: =IFERROR(I55/I7,"-") -> - | J43: =IFERROR(J55/J7,"-") -> - | ... O43: =IFERROR(O55/O7,"-") -> 0.11777778
...

Sheet Safety
C1: Actual | D1: Actual | E1: Actual | F1: Actual | G1: Actual | H1: Actual | I1: Actual | J1: Actual | K1: FCAST09 | L1: FCAST09 | M1: FCAST09 | N1: FCAST09
B2: Scenario# | C2: Actual | D2: Actual | E2: Actual | F2: Actual | G2: Actual | H2: Actual | I2: Actual | J2: Actual | K2: Actual | L2: Actual | M2: Actual | N2: Actual
B5: Year# | C5: 2026 | D5: 2026 | E5: 2026 | F5: 2026 | G5: 2026 | H5: 2026 | I5: 2026 | J5: 2026 | K5: 2026 | L5: 2026 | M5: 2026 | N5: 2026
B8: Period# | C8: P01 | D8: P02 | E8: P03 | F8: P04 | G8: P05 | H8: P06 | I8: P07 | J8: P08 | K8: P09 | L8: P10 | M8: P11 | N8: P12
B9: Account#
B10: ICP#
B11: Custom1# | C11: TotalC1 | D11: TotalC1 | E11: TotalC1 | F11: TotalC1 | G11: TotalC1 | H11: TotalC1 | I11: TotalC1 | J11: TotalC1 | K11: TotalC1 | L11: TotalC1 | M11: TotalC1 | N11: TotalC1
B12: Custom2# | C12: TotalC2 | D12: TotalC2 | E12: TotalC2 | F12: TotalC2 | G12: TotalC2 | H12: TotalC2 | I12: TotalC2 | J12: TotalC2 | K12: TotalC2 | L12: TotalC2 | M12: TotalC2 | N12: TotalC2
B13: Custom3#
B14: Custom4#
B18: View# | C18: Periodic | D18: Periodic | E18: Periodic | F18: Periodic | G18: Periodic | H18: Periodic | I18: Periodic | J18: Periodic | K18: Periodic | L18: Periodic | M18: Periodic | N18: Periodic
B19: Value# | C19: USD Total | D19: USD Total | E19: USD Total | F19: USD Total | G19: USD Total | H19: USD Total | I19: USD Total | J19: USD Total | K19: USD Total | L19: USD Total | M19: USD Total | N19: USD Total
B21: TRAINING DATA ONLY - Zava Safety and all business names and numbers are fictitious. Layout mirrors a typical HFM / Cognos reporting pack.
B22: SAFECON_2DISP
B23: Zava Safety - Consolidated | BU23: FCAST10 - Variance ($) - Favorable / (Unfavorable)
C24: FCAST09 as Reported | Q24: FCAST09 at New Fx Rates | AE24: Fx Changes | AS24: Operational Adjustments | BG24: FCAST10 | BU24: Through Sep | BY24: Rest of Year | CC24: Full Year
C25: Actual | D25: Actual | E25: Actual | F25: Actual | G25: Actual | H25: Actual | I25: Actual | J25: Actual | K25: FCAST09 | L25: FCAST09 | M25: FCAST09 | N25: FCAST09 | O25: Forecast | Q25: Actual | R25: Actual | S25: Actual | T25: Actual | U25: Actual | V25: Actual | W25: Actual | X25: Actual | Y25: FCAST09 | Z25: FCAST09 | AA25: FCAST09 | AB25: FCAST09 | AC25: Forecast | BG25: Actual | BH25: Actual | BI25: Actual | BJ25: Actual | BK25: Actual | BL25: Actual | BM25: Actual | BN25: Actual | BO25: Actual | BP25: FCAST10 | BQ25: FCAST10 | BR25: FCAST10 | BS25: Forecast
B26: Description: | C26: January | D26: February | E26: March | F26: April | G26: May | H26: June | I26: July | J26: August | K26: September | L26: October | M26: November | N26: December | O26: Full year | Q26: January | R26: February | S26: March | T26: April | U26: May | V26: June | W26: July | X26: August | Y26: September | Z26: October | AA26: November | AB26: December | AC26: Full year | AE26: January | AF26: February | AG26: March | AH26: April | AI26: May | AJ26: June | AK26: July | AL26: August | AM26: September | AN26: October | AO26: November | AP26: December | AQ26: Full year | AS26: January | AT26: February | AU26: March | AV26: April | AW26: May | AX26: June | AY26: July | AZ26: August | BA26: September | BB26: October | BC26: November | BD26: December | BE26: Full year | BG26: January | BH26: February | BI26: March | BJ26: April | BK26: May | BL26: June | BM26: July | BN26: August | BO26: September | BP26: October | BQ26: November | BR26: December | BS26: Full year | BU26: Actual vs. FCAST09 | BV26: Actual vs. Bud | BW26: Actual vs. PY | BY26: FCAST10 vs. FCAST09 | BZ26: FCAST10 vs. Bud | CA26: FCAST10 vs. PY | CC26: FCAST10 vs. FCAST09 | CD26: FCAST10 vs. Bud | CE26: FCAST10 vs. PY
B28: Sales | C28: ='Alder'!C28+'Beacon'!C28+'Cobalt'!C28+'Delta'!C28+'Ember'!C28+'Falcon'!C28+'Granite'!C28+'Hollis'!C28+'SAFEREG'!C28 -> 49776.7 | D28: ='Alder'!D28+'Beacon'!D28+'Cobalt'!D28+'Delta'!D28+'Ember'!D28+'Falcon'!D28+'Granite'!D28+'Hollis'!D28+'SAFEREG'!D28 -> 49033.4 | E28: ='Alder'!E28+'Beacon'!E28+'Cobalt'!E28+'Delta'!E28+'Ember'!E28+'Falcon'!E28+'Granite'!E28+'Hollis'!E28+'SAFEREG'!E28 -> 52588.4 | F28: ='Alder'!F28+'Beacon'!F28+'Cobalt'!F28+'Delta'!F28+'Ember'!F28+'Falcon'!F28+'Granite'!F28+'Hollis'!F28+'SAFEREG'!F28 -> 56881.9 | G28: ='Alder'!G28+'Beacon'!G28+'Cobalt'!G28+'Delta'!G28+'Ember'!G28+'Falcon'!G28+'Granite'!G28+'Hollis'!G28+'SAFEREG'!G28 -> 51833.5 | H28: ='Alder'!H28+'Beacon'!H28+'Cobalt'!H28+'Delta'!H28+'Ember'!H28+'Falcon'!H28+'Granite'!H28+'Hollis'!H28+'SAFEREG'!H28 -> 54124.1 | I28: ='Alder'!I28+'Beacon'!I28+'Cobalt'!I28+'Delta'!I28+'Ember'!I28+'Falcon'!I28+'Granite'!I28+'Hollis'!I28+'SAFEREG'!I28 -> 53826.7 | J28: ='Alder'!J28+'Beacon'!J28+'Cobalt'!J28+'Delta'!J28+'Ember'!J28+'Falcon'!J28+'Granite'!J28+'Hollis'!J28+'SAFEREG'!J28 -> 52681.3 | ... N28: ='Alder'!N28+'Beacon'!N28+'Cobalt'!N28+'Delta'!N28+'Ember'!N28+'Falcon'!N28+'Granite'!N28+'Hollis'!N28+'SAFEREG'!N28 -> 54989.2 | O28: =SUM(C28:N28) -> 633766.9 | Q28: ='Alder'!Q28+'Beacon'!Q28+'Cobalt'!Q28+'Delta'!Q28+'Ember'!Q28+'Falcon'!Q28+'Granite'!Q28+'Hollis'!Q28+'SAFEREG'!Q28 -> 49776.7 | R28: ='Alder'!R28+'Beacon'!R28+'Cobalt'!R28+'Delta'!R28+'Ember'!R28+'Falcon'!R28+'Granite'!R28+'Hollis'!R28+'SAFEREG'!R28 -> 49033.4 | S28: ='Alder'!S28+'Beacon'!S28+'Cobalt'!S28+'Delta'!S28+'Ember'!S28+'Falcon'!S28+'Granite'!S28+'Hollis'!S28+'SAFEREG'!S28 -> 52588.4 | T28: ='Alder'!T28+'Beacon'!T28+'Cobalt'!T28+'Delta'!T28+'Ember'!T28+'Falcon'!T28+'Granite'!T28+'Hollis'!T28+'SAFEREG'!T28 -> 56881.9 | U28: ='Alder'!U28+'Beacon'!U28+'Cobalt'!U28+'Delta'!U28+'Ember'!U28+'Falcon'!U28+'Granite'!U28+'Hollis'!U28+'SAFEREG'!U28 -> 51833.5 | V28: ='Alder'!V28+'Beacon'!V28+'Cobalt'!V28+'Delta'!V28+'Ember'!V28+'Falcon'!V28+'Granite'!V28+'Hollis'!V28+'SAFEREG'!V28 -> 54124.1 | W28: ='Alder'!W28+'Beacon'!W28+'Cobalt'!W28+'Delta'!W28+'Ember'!W28+'Falcon'!W28+'Granite'!W28+'Hollis'!W28+'SAFEREG'!W28 -> 53826.7 | X28: ='Alder'!X28+'Beacon'!X28+'Cobalt'!X28+'Delta'!X28+'Ember'!X28+'Falcon'!X28+'Granite'!X28+'Hollis'!X28+'SAFEREG'!X28 -> 52681.3 | ... AB28: ='Alder'!AB28+'Beacon'!AB28+'Cobalt'!AB28+'Delta'!AB28+'Ember'!AB28+'Falcon'!AB28+'Granite'!AB28+'Hollis'!AB28+'SAFEREG'!AB28 -> 54944.2 | AC28: =SUM(Q28:AB28) -> 633586.9 | AE28: =Q28-C28 -> 0 | AF28: =R28-D28 -> 0 | AG28: =S28-E28 -> 0 | AH28: =T28-F28 -> 0 | AI28: =U28-G28 -> 0 | AJ28: =V28-H28 -> 0 | AK28: =W28-I28 -> 0 | AL28: =X28-J28 -> 0 | ... AP28: =AB28-N28 -> -45 | AQ28: =SUM(AE28:AP28) -> -180 | AS28: ='Safety-Adj'!C15 -> 0 | AT28: ='Safety-Adj'!D15 -> 0 | AU28: ='Safety-Adj'!E15 -> 0 | AV28: ='Safety-Adj'!F15 -> 0 | AW28: ='Safety-Adj'!G15 -> 0 | AX28: ='Safety-Adj'!H15 -> 0 | AY28: ='Safety-Adj'!I15 -> 0 | AZ28: ='Safety-Adj'!J15 -> 0 | ... BD28: ='Safety-Adj'!N15 -> 340 | BE28: =SUM(AS28:BD28) -> 570 | BG28: =C28+AE28+AS28 -> 49776.7 | BH28: =D28+AF28+AT28 -> 49033.4 | BI28: =E28+AG28+AU28 -> 52588.4 | BJ28: =F28+AH28+AV28 -> 56881.9 | BK28: =G28+AI28+AW28 -> 51833.5 | BL28: =H28+AJ28+AX28 -> 54124.1 | BM28: =I28+AK28+AY28 -> 53826.7 | BN28: =J28+AL28+AZ28 -> 52681.3 | ... BR28: =N28+AP28+BD28 -> 55284.2 | BS28: =SUM(BG28:BR28) -> 634156.9 | BU28: =SUM(BG28:BO28)-SUM(C28:K28) -> 1445 | BV28: =SUM(BG28:BO28)-SUM(C51:K51) -> 10937.5 | BW28: =SUM(BG28:BO28)-SUM(C64:K64) -> 32001.3 | BY28: =SUM(BP28:BR28)-SUM(L28:N28) -> -1055 | BZ28: =SUM(BP28:BR28)-SUM(L51:N51) -> 3221.3 | CA28: =SUM(BP28:BR28)-SUM(L64:N64) -> 10243.2 | CC28: =BS28-O28 -> 390 | CD28: =BS28-O51 -> 14158.8 | CE28: =BS28-O64 -> 42244.5
B29: Gross Margin | C29: ='Alder'!C29+'Beacon'!C29+'Cobalt'!C29+'Delta'!C29+'Ember'!C29+'Falcon'!C29+'Granite'!C29+'Hollis'!C29+'SAFEREG'!C29 -> 15735.6 | D29: ='Alder'!D29+'Beacon'!D29+'Cobalt'!D29+'Delta'!D29+'Ember'!D29+'Falcon'!D29+'Granite'!D29+'Hollis'!D29+'SAFEREG'!D29 -> 15444.8 | E29: ='Alder'!E29+'Beacon'!E29+'Cobalt'!E29+'Delta'!E29+'Ember'!E29+'Falcon'!E29+'Granite'!E29+'Hollis'!E29+'SAFEREG'!E29 -> 16536.9 | F29: ='Alder'!F29+'Beacon'!F29+'Cobalt'!F29+'Delta'!F29+'Ember'!F29+'Falcon'!F29+'Granite'!F29+'Hollis'!F29+'SAFEREG'!F29 -> 17939.6 | G29: ='Alder'!G29+'Beacon'!G29+'Cobalt'!G29+'Delta'!G29+'Ember'!G29+'Falcon'!G29+'Granite'!G29+'Hollis'!G29+'SAFEREG'!G29 -> 16345.6 | H29: ='Alder'!H29+'Beacon'!H29+'Cobalt'!H29+'Delta'!H29+'Ember'!H29+'Falcon'!H29+'Granite'!H29+'Hollis'!H29+'SAFEREG'!H29 -> 16785.8 | I29: ='Alder'!I29+'Beacon'!I29+'Cobalt'!I29+'Delta'!I29+'Ember'!I29+'Falcon'!I29+'Granite'!I29+'Hollis'!I29+'SAFEREG'!I29 -> 16677.1 | J29: ='Alder'!J29+'Beacon'!J29+'Cobalt'!J29+'Delta'!J29+'Ember'!J29+'Falcon'!J29+'Granite'!J29+'Hollis'!J29+'SAFEREG'!J29 -> 16298.9 | ... N29: ='Alder'!N29+'Beacon'!N29+'Cobalt'!N29+'Delta'!N29+'Ember'!N29+'Falcon'!N29+'Granite'!N29+'Hollis'!N29+'SAFEREG'!N29 -> 17008.3 | O29: =SUM(C29:N29) -> 197718.7 | Q29: ='Alder'!Q29+'Beacon'!Q29+'Cobalt'!Q29+'Delta'!Q29+'Ember'!Q29+'Falcon'!Q29+'Granite'!Q29+'Hollis'!Q29+'SAFEREG'!Q29 -> 15735.6 | R29: ='Alder'!R29+'Beacon'!R29+'Cobalt'!R29+'Delta'!R29+'Ember'!R29+'Falcon'!R29+'Granite'!R29+'Hollis'!R29+'SAFEREG'!R29 -> 15444.8 | S29: ='Alder'!S29+'Beacon'!S29+'Cobalt'!S29+'Delta'!S29+'Ember'!S29+'Falcon'!S29+'Granite'!S29+'Hollis'!S29+'SAFEREG'!S29 -> 16536.9 | T29: ='Alder'!T29+'Beacon'!T29+'Cobalt'!T29+'Delta'!T29+'Ember'!T29+'Falcon'!T29+'Granite'!T29+'Hollis'!T29+'SAFEREG'!T29 -> 17939.6 | U29: ='Alder'!U29+'Beacon'!U29+'Cobalt'!U29+'Delta'!U29+'Ember'!U29+'Falcon'!U29+'Granite'!U29+'Hollis'!U29+'SAFEREG'!U29 -> 16345.6 | V29: ='Alder'!V29+'Beacon'!V29+'Cobalt'!V29+'Delta'!V29+'Ember'!V29+'Falcon'!V29+'Granite'!V29+'Hollis'!V29+'SAFEREG'!V29 -> 16785.8 | W29: ='Alder'!W29+'Beacon'!W29+'Cobalt'!W29+'Delta'!W29+'Ember'!W29+'Falcon'!W29+'Granite'!W29+'Hollis'!W29+'SAFEREG'!W29 -> 16677.1 | X29: ='Alder'!X29+'Beacon'!X29+'Cobalt'!X29+'Delta'!X29+'Ember'!X29+'Falcon'!X29+'Granite'!X29+'Hollis'!X29+'SAFEREG'!X29 -> 16298.9 | ... AB29: ='Alder'!AB29+'Beacon'!AB29+'Cobalt'!AB29+'Delta'!AB29+'Ember'!AB29+'Falcon'!AB29+'Granite'!AB29+'Hollis'!AB29+'SAFEREG'!AB29 -> 16995.3 | AC29: =SUM(Q29:AB29) -> 197666.7 | AE29: =Q29-C29 -> 0 | AF29: =R29-D29 -> 0 | AG29: =S29-E29 -> 0 | AH29: =T29-F29 -> 0 | AI29: =U29-G29 -> 0 | AJ29: =V29-H29 -> 0 | AK29: =W29-I29 -> 0 | AL29: =X29-J29 -> 0 | ... AP29: =AB29-N29 -> -13 | AQ29: =SUM(AE29:AP29) -> -52 | AS29: ='Safety-Adj'!C39+'Safety-Adj'!C83 -> 0 | AT29: ='Safety-Adj'!D39+'Safety-Adj'!D83 -> 0 | AU29: ='Safety-Adj'!E39+'Safety-Adj'!E83 -> 0 | AV29: ='Safety-Adj'!F39+'Safety-Adj'!F83 -> 0 | AW29: ='Safety-Adj'!G39+'Safety-Adj'!G83 -> 0 | AX29: ='Safety-Adj'!H39+'Safety-Adj'!H83 -> 0 | AY29: ='Safety-Adj'!I39+'Safety-Adj'!I83 -> 0 | AZ29: ='Safety-Adj'!J39+'Safety-Adj'!J83 -> 0 | ... BD29: ='Safety-Adj'!N39+'Safety-Adj'!N83 -> 239.08 | BE29: =SUM(AS29:BD29) -> -134.68 | BG29: =C29+AE29+AS29 -> 15735.6 | BH29: =D29+AF29+AT29 -> 15444.8 | BI29: =E29+AG29+AU29 -> 16536.9 | BJ29: =F29+AH29+AV29 -> 17939.6 | BK29: =G29+AI29+AW29 -> 16345.6 | BL29: =H29+AJ29+AX29 -> 16785.8 | BM29: =I29+AK29+AY29 -> 16677.1 | BN29: =J29+AL29+AZ29 -> 16298.9 | ... BR29: =N29+AP29+BD29 -> 17234.38 | BS29: =SUM(BG29:BR29) -> 197532.02 | BU29: =SUM(BG29:BO29)-SUM(C29:K29) -> -85.92 | BV29: =SUM(BG29:BO29)-SUM(C52:K52) -> 2279.88 | BW29: =SUM(BG29:BO29)-SUM(C65:K65) -> 8917.68 | BY29: =SUM(BP29:BR29)-SUM(L29:N29) -> -100.76 | BZ29: =SUM(BP29:BR29)-SUM(L52:N52) -> 502.64 | CA29: =SUM(BP29:BR29)-SUM(L65:N65) -> 2634.14 | CC29: =BS29-O29 -> -186.68 | CD29: =BS29-O52 -> 2782.52 | CE29: =BS29-O65 -> 11551.82
B30: Op Costs | C30: ='Alder'!C30+'Beacon'!C30+'Cobalt'!C30+'Delta'!C30+'Ember'!C30+'Falcon'!C30+'Granite'!C30+'Hollis'!C30+'SAFEREG'!C30 -> -10738.6 | D30: ='Alder'!D30+'Beacon'!D30+'Cobalt'!D30+'Delta'!D30+'Ember'!D30+'Falcon'!D30+'Granite'!D30+'Hollis'!D30+'SAFEREG'!D30 -> -10538.3 | E30: ='Alder'!E30+'Beacon'!E30+'Cobalt'!E30+'Delta'!E30+'Ember'!E30+'Falcon'!E30+'Granite'!E30+'Hollis'!E30+'SAFEREG'!E30 -> -11305 | F30: ='Alder'!F30+'Beacon'!F30+'Cobalt'!F30+'Delta'!F30+'Ember'!F30+'Falcon'!F30+'Granite'!F30+'Hollis'!F30+'SAFEREG'!F30 -> -12182 | G30: ='Alder'!G30+'Beacon'!G30+'Cobalt'!G30+'Delta'!G30+'Ember'!G30+'Falcon'!G30+'Granite'!G30+'Hollis'!G30+'SAFEREG'!G30 -> -11125.4 | H30: ='Alder'!H30+'Beacon'!H30+'Cobalt'!H30+'Delta'!H30+'Ember'!H30+'Falcon'!H30+'Granite'!H30+'Hollis'!H30+'SAFEREG'!H30 -> -11606 | I30: ='Alder'!I30+'Beacon'!I30+'Cobalt'!I30+'Delta'!I30+'Ember'!I30+'Falcon'!I30+'Granite'!I30+'Hollis'!I30+'SAFEREG'!I30 -> -11507 | J30: ='Alder'!J30+'Beacon'!J30+'Cobalt'!J30+'Delta'!J30+'Ember'!J30+'Falcon'!J30+'Granite'!J30+'Hollis'!J30+'SAFEREG'!J30 -> -11490.8 | ... N30: ='Alder'!N30+'Beacon'!N30+'Cobalt'!N30+'Delta'!N30+'Ember'!N30+'Falcon'!N30+'Granite'!N30+'Hollis'!N30+'SAFEREG'!N30 -> -11658.7 | O30: =SUM(C30:N30) -> -135761.7 | Q30: ='Alder'!Q30+'Beacon'!Q30+'Cobalt'!Q30+'Delta'!Q30+'Ember'!Q30+'Falcon'!Q30+'Granite'!Q30+'Hollis'!Q30+'SAFEREG'!Q30 -> -10738.6 | R30: ='Alder'!R30+'Beacon'!R30+'Cobalt'!R30+'Delta'!R30+'Ember'!R30+'Falcon'!R30+'Granite'!R30+'Hollis'!R30+'SAFEREG'!R30 -> -10538.3 | S30: ='Alder'!S30+'Beacon'!S30+'Cobalt'!S30+'Delta'!S30+'Ember'!S30+'Falcon'!S30+'Granite'!S30+'Hollis'!S30+'SAFEREG'!S30 -> -11305 | T30: ='Alder'!T30+'Beacon'!T30+'Cobalt'!T30+'Delta'!T30+'Ember'!T30+'Falcon'!T30+'Granite'!T30+'Hollis'!T30+'SAFEREG'!T30 -> -12182 | U30: ='Alder'!U30+'Beacon'!U30+'Cobalt'!U30+'Delta'!U30+'Ember'!U30+'Falcon'!U30+'Granite'!U30+'Hollis'!U30+'SAFEREG'!U30 -> -11125.4 | V30: ='Alder'!V30+'Beacon'!V30+'Cobalt'!V30+'Delta'!V30+'Ember'!V30+'Falcon'!V30+'Granite'!V30+'Hollis'!V30+'SAFEREG'!V30 -> -11606 | W30: ='Alder'!W30+'Beacon'!W30+'Cobalt'!W30+'Delta'!W30+'Ember'!W30+'Falcon'!W30+'Granite'!W30+'Hollis'!W30+'SAFEREG'!W30 -> -11507 | X30: ='Alder'!X30+'Beacon'!X30+'Cobalt'!X30+'Delta'!X30+'Ember'!X30+'Falcon'!X30+'Granite'!X30+'Hollis'!X30+'SAFEREG'!X30 -> -11490.8 | ... AB30: ='Alder'!AB30+'Beacon'!AB30+'Cobalt'!AB30+'Delta'!AB30+'Ember'!AB30+'Falcon'!AB30+'Granite'!AB30+'Hollis'!AB30+'SAFEREG'!AB30 -> -11649.7 | AC30: =SUM(Q30:AB30) -> -135725.7 | AE30: =Q30-C30 -> 0 | AF30: =R30-D30 -> 0 | AG30: =S30-E30 -> 0 | AH30: =T30-F30 -> 0 | AI30: =U30-G30 -> 0 | AJ30: =V30-H30 -> 0 | AK30: =W30-I30 -> 0 | AL30: =X30-J30 -> 0 | ... AP30: =AB30-N30 -> 9 | AQ30: =SUM(AE30:AP30) -> 36 | AS30: =-'Safety-Adj'!C63-'Safety-Adj'!C89 -> 0 | AT30: =-'Safety-Adj'!D63-'Safety-Adj'!D89 -> 0 | AU30: =-'Safety-Adj'!E63-'Safety-Adj'!E89 -> 0 | AV30: =-'Safety-Adj'!F63-'Safety-Adj'!F89 -> 0 | AW30: =-'Safety-Adj'!G63-'Safety-Adj'!G89 -> 0 | AX30: =-'Safety-Adj'!H63-'Safety-Adj'!H89 -> 0 | AY30: =-'Safety-Adj'!I63-'Safety-Adj'!I89 -> 0 | AZ30: =-'Safety-Adj'!J63-'Safety-Adj'!J89 -> 0 | ... BD30: =-'Safety-Adj'!N63-'Safety-Adj'!N89 -> 227 | BE30: =SUM(AS30:BD30) -> 738 | BG30: =C30+AE30+AS30 -> -10738.6 | BH30: =D30+AF30+AT30 -> -10538.3 | BI30: =E30+AG30+AU30 -> -11305 | BJ30: =F30+AH30+AV30 -> -12182 | BK30: =G30+AI30+AW30 -> -11125.4 | BL30: =H30+AJ30+AX30 -> -11606 | BM30: =I30+AK30+AY30 -> -11507 | BN30: =J30+AL30+AZ30 -> -11490.8 | ... BR30: =N30+AP30+BD30 -> -11422.7 | BS30: =SUM(BG30:BR30) -> -134987.7 | BU30: =SUM(BG30:BO30)-SUM(C30:K30) -> 151 | BV30: =SUM(BG30:BO30)-SUM(C53:K53) -> -634.1 | BW30: =SUM(BG30:BO30)-SUM(C66:K66) -> -3569 | BY30: =SUM(BP30:BR30)-SUM(L30:N30) -> 623 | BZ30: =SUM(BP30:BR30)-SUM(L53:N53) -> 372.8 | CA30: =SUM(BP30:BR30)-SUM(L66:N66) -> -637.7 | CC30: =BS30-O30 -> 774 | CD30: =BS30-O53 -> -261.3 | CE30: =BS30-O66 -> -4206.7
B31: PBITA | C31: =C29+C30 -> 4997 | D31: =D29+D30 -> 4906.5 | E31: =E29+E30 -> 5231.9 | F31: =F29+F30 -> 5757.6 | G31: =G29+G30 -> 5220.2 | H31: =H29+H30 -> 5179.8 | I31: =I29+I30 -> 5170.1 | J31: =J29+J30 -> 4808.1 | ... N31: =N29+N30 -> 5349.6 | O31: =SUM(C31:N31) -> 61957 | Q31: =Q29+Q30 -> 4997 | R31: =R29+R30 -> 4906.5 | S31: =S29+S30 -> 5231.9 | T31: =T29+T30 -> 5757.6 | U31: =U29+U30 -> 5220.2 | V31: =V29+V30 -> 5179.8 | W31: =W29+W30 -> 5170.1 | X31: =X29+X30 -> 4808.1 | ... AB31: =AB29+AB30 -> 5345.6 | AC31: =SUM(Q31:AB31) -> 61941 | AE31: =AE29+AE30 -> 0 | AF31: =AF29+AF30 -> 0 | AG31: =AG29+AG30 -> 0 | AH31: =AH29+AH30 -> 0 | AI31: =AI29+AI30 -> 0 | AJ31: =AJ29+AJ30 -> 0 | AK31: =AK29+AK30 -> 0 | AL31: =AL29+AL30 -> 0 | ... AP31: =AP29+AP30 -> -4 | AQ31: =SUM(AE31:AP31) -> -16 | AS31: =AS29+AS30 -> 0 | AT31: =AT29+AT30 -> 0 | AU31: =AU29+AU30 -> 0 | AV31: =AV29+AV30 -> 0 | AW31: =AW29+AW30 -> 0 | AX31: =AX29+AX30 -> 0 | AY31: =AY29+AY30 -> 0 | AZ31: =AZ29+AZ30 -> 0 | ... BD31: =BD29+BD30 -> 466.08 | BE31: =SUM(AS31:BD31) -> 603.32 | BG31: =BG29+BG30 -> 4997 | BH31: =BH29+BH30 -> 4906.5 | BI31: =BI29+BI30 -> 5231.9 | BJ31: =BJ29+BJ30 -> 5757.6 | BK31: =BK29+BK30 -> 5220.2 | BL31: =BL29+BL30 -> 5179.8 | BM31: =BM29+BM30 -> 5170.1 | BN31: =BN29+BN30 -> 4808.1 | ... BR31: =BR29+BR30 -> 5811.68 | BS31: =SUM(BG31:BR31) -> 62544.32 | BU31: =SUM(BG31:BO31)-SUM(C31:K31) -> 65.08 | BV31: =SUM(BG31:BO31)-SUM(C54:K54) -> 1645.78 | BW31: =SUM(BG31:BO31)-SUM(C67:K67) -> 5348.68 | BY31: =SUM(BP31:BR31)-SUM(L31:N31) -> 522.24 | BZ31: =SUM(BP31:BR31)-SUM(L54:N54) -> 875.44 | CA31: =SUM(BP31:BR31)-SUM(L67:N67) -> 1996.44 | CC31: =BS31-O31 -> 587.32 | CD31: =BS31-O54 -> 2521.22 | CE31: =BS31-O67 -> 7345.12
B35: GM % | C35: =IFERROR(C29/C28,0) -> 0.31612381 | D35: =IFERROR(D29/D28,0) -> 0.3149853 | E35: =IFERROR(E29/E28,0) -> 0.31445908 | F35: =IFERROR(F29/F28,0) -> 0.31538328 | G35: =IFERROR(G29/G28,0) -> 0.31534818 | H35: =IFERROR(H29/H28,0) -> 0.31013541 | I35: =IFERROR(I29/I28,0) -> 0.30982951 | J35: =IFERROR(J29/J28,0) -> 0.30938682 | ... O35: =IFERROR(O29/O28,0) -> 0.31197385 | Q35: =IFERROR(Q29/Q28,0) -> 0.31612381 | R35: =IFERROR(R29/R28,0) -> 0.3149853 | S35: =IFERROR(S29/S28,0) -> 0.31445908 | T35: =IFERROR(T29/T28,0) -> 0.31538328 | U35: =IFERROR(U29/U28,0) -> 0.31534818 | V35: =IFERROR(V29/V28,0) -> 0.31013541 | W35: =IFERROR(W29/W28,0) -> 0.30982951 | X35: =IFERROR(X29/X28,0) -> 0.30938682 | ... AC35: =IFERROR(AC29/AC28,0) -> 0.31198041 | AE35: =IFERROR(AE29/AE28,0) -> 0 | AF35: =IFERROR(AF29/AF28,0) -> 0 | AG35: =IFERROR(AG29/AG28,0) -> 0 | AH35: =IFERROR(AH29/AH28,0) -> 0 | AI35: =IFERROR(AI29/AI28,0) -> 0 | AJ35: =IFERROR(AJ29/AJ28,0) -> 0 | AK35: =IFERROR(AK29/AK28,0) -> 0 | AL35: =IFERROR(AL29/AL28,0) -> 0 | ... AQ35: =IFERROR(AQ29/AQ28,0) -> 0.28888889 | AS35: =IFERROR(AS29/AS28,0) -> 0 | AT35: =IFERROR(AT29/AT28,0) -> 0 | AU35: =IFERROR(AU29/AU28,0) -> 0 | AV35: =IFERROR(AV29/AV28,0) -> 0 | AW35: =IFERROR(AW29/AW28,0) -> 0 | AX35: =IFERROR(AX29/AX28,0) -> 0 | AY35: =IFERROR(AY29/AY28,0) -> 0 | AZ35: =IFERROR(AZ29/AZ28,0) -> 0 | ... BE35: =IFERROR(BE29/BE28,0) -> -0.2362807 | BG35: =IFERROR(BG29/BG28,0) -> 0.31612381 | BH35: =IFERROR(BH29/BH28,0) -> 0.3149853 | BI35: =IFERROR(BI29/BI28,0) -> 0.31445908 | BJ35: =IFERROR(BJ29/BJ28,0) -> 0.31538328 | BK35: =IFERROR(BK29/BK28,0) -> 0.31534818 | BL35: =IFERROR(BL29/BL28,0) -> 0.31013541 | BM35: =IFERROR(BM29/BM28,0) -> 0.30982951 | BN35: =IFERROR(BN29/BN28,0) -> 0.30938682 | ... BS35: =IFERROR(BS29/BS28,0) -> 0.31148761
B36: Op Cost % | C36: =IFERROR(C30/C28,0) -> -0.21573547 | D36: =IFERROR(D30/D28,0) -> -0.21492085 | E36: =IFERROR(E30/E28,0) -> -0.21497136 | F36: =IFERROR(F30/F28,0) -> -0.21416303 | G36: =IFERROR(G30/G28,0) -> -0.21463725 | H36: =IFERROR(H30/H28,0) -> -0.21443313 | I36: =IFERROR(I30/I28,0) -> -0.21377866 | J36: =IFERROR(J30/J28,0) -> -0.21811914 | ... O36: =IFERROR(O30/O28,0) -> -0.21421393 | Q36: =IFERROR(Q30/Q28,0) -> -0.21573547 | R36: =IFERROR(R30/R28,0) -> -0.21492085 | S36: =IFERROR(S30/S28,0) -> -0.21497136 | T36: =IFERROR(T30/T28,0) -> -0.21416303 | U36: =IFERROR(U30/U28,0) -> -0.21463725 | V36: =IFERROR(V30/V28,0) -> -0.21443313 | W36: =IFERROR(W30/W28,0) -> -0.21377866 | X36: =IFERROR(X30/X28,0) -> -0.21811914 | ... AC36: =IFERROR(AC30/AC28,0) -> -0.21421797 | AE36: =IFERROR(AE30/AE28,0) -> 0 | AF36: =IFERROR(AF30/AF28,0) -> 0 | AG36: =IFERROR(AG30/AG28,0) -> 0 | AH36: =IFERROR(AH30/AH28,0) -> 0 | AI36: =IFERROR(AI30/AI28,0) -> 0 | AJ36: =IFERROR(AJ30/AJ28,0) -> 0 | AK36: =IFERROR(AK30/AK28,0) -> 0 | AL36: =IFERROR(AL30/AL28,0) -> 0 | ... AQ36: =IFERROR(AQ30/AQ28,0) -> -0.2 | AS36: =IFERROR(AS30/AS28,0) -> 0 | AT36: =IFERROR(AT30/AT28,0) -> 0 | AU36: =IFERROR(AU30/AU28,0) -> 0 | AV36: =IFERROR(AV30/AV28,0) -> 0 | AW36: =IFERROR(AW30/AW28,0) -> 0 | AX36: =IFERROR(AX30/AX28,0) -> 0 | AY36: =IFERROR(AY30/AY28,0) -> 0 | AZ36: =IFERROR(AZ30/AZ28,0) -> 0 | ... BE36: =IFERROR(BE30/BE28,0) -> 1.2947368 | BG36: =IFERROR(BG30/BG28,0) -> -0.21573547 | BH36: =IFERROR(BH30/BH28,0) -> -0.21492085 | BI36: =IFERROR(BI30/BI28,0) -> -0.21497136 | BJ36: =IFERROR(BJ30/BJ28,0) -> -0.21416303 | BK36: =IFERROR(BK30/BK28,0) -> -0.21463725 | BL36: =IFERROR(BL30/BL28,0) -> -0.21443313 | BM36: =IFERROR(BM30/BM28,0) -> -0.21377866 | BN36: =IFERROR(BN30/BN28,0) -> -0.21811914 | ... BS36: =IFERROR(BS30/BS28,0) -> -0.21286168
B37: PBITA % | C37: =IFERROR(C31/C28,0) -> 0.10038833 | D37: =IFERROR(D31/D28,0) -> 0.10006445 | E37: =IFERROR(E31/E28,0) -> 0.09948772 | F37: =IFERROR(F31/F28,0) -> 0.10122025 | G37: =IFERROR(G31/G28,0) -> 0.10071093 | H37: =IFERROR(H31/H28,0) -> 0.095702284 | I37: =IFERROR(I31/I28,0) -> 0.096050845 | J37: =IFERROR(J31/J28,0) -> 0.091267679 | ... O37: =IFERROR(O31/O28,0) -> 0.097759918 | Q37: =IFERROR(Q31/Q28,0) -> 0.10038833 | R37: =IFERROR(R31/R28,0) -> 0.10006445 | S37: =IFERROR(S31/S28,0) -> 0.09948772 | T37: =IFERROR(T31/T28,0) -> 0.10122025 | U37: =IFERROR(U31/U28,0) -> 0.10071093 | V37: =IFERROR(V31/V28,0) -> 0.095702284 | W37: =IFERROR(W31/W28,0) -> 0.096050845 | X37: =IFERROR(X31/X28,0) -> 0.091267679 | ... AC37: =IFERROR(AC31/AC28,0) -> 0.097762438 | AE37: =IFERROR(AE31/AE28,0) -> 0 | AF37: =IFERROR(AF31/AF28,0) -> 0 | AG37: =IFERROR(AG31/AG28,0) -> 0 | AH37: =IFERROR(AH31/AH28,0) -> 0 | AI37: =IFERROR(AI31/AI28,0) -> 0 | AJ37: =IFERROR(AJ31/AJ28,0) -> 0 | AK37: =IFERROR(AK31/AK28,0) -> 0 | AL37: =IFERROR(AL31/AL28,0) -> 0 | ... AQ37: =IFERROR(AQ31/AQ28,0) -> 0.088888889 | AS37: =IFERROR(AS31/AS28,0) -> 0 | AT37: =IFERROR(AT31/AT28,0) -> 0 | AU37: =IFERROR(AU31/AU28,0) -> 0 | AV37: =IFERROR(AV31/AV28,0) -> 0 | AW37: =IFERROR(AW31/AW28,0) -> 0 | AX37: =IFERROR(AX31/AX28,0) -> 0 | AY37: =IFERROR(AY31/AY28,0) -> 0 | AZ37: =IFERROR(AZ31/AZ28,0) -> 0 | ... BE37: =IFERROR(BE31/BE28,0) -> 1.0584561 | BG37: =IFERROR(BG31/BG28,0) -> 0.10038833 | BH37: =IFERROR(BH31/BH28,0) -> 0.10006445 | BI37: =IFERROR(BI31/BI28,0) -> 0.09948772 | BJ37: =IFERROR(BJ31/BJ28,0) -> 0.10122025 | BK37: =IFERROR(BK31/BK28,0) -> 0.10071093 | BL37: =IFERROR(BL31/BL28,0) -> 0.095702284 | BM37: =IFERROR(BM31/BM28,0) -> 0.096050845 | BN37: =IFERROR(BN31/BN28,0) -> 0.091267679 | ... BS37: =IFERROR(BS31/BS28,0) -> 0.098625939
B38: Sales/Day | C38: =IFERROR(C28/21,0) -> 2370.319 | D38: =IFERROR(D28/20,0) -> 2451.67 | E38: =IFERROR(E28/22,0) -> 2390.3818 | F38: =IFERROR(F28/22,0) -> 2585.5409 | G38: =IFERROR(G28/20,0) -> 2591.675 | H38: =IFERROR(H28/22,0) -> 2460.1864 | I38: =IFERROR(I28/22,0) -> 2446.6682 | J38: =IFERROR(J28/21,0) -> 2508.6333 | K38: =IFERROR(K28/21,0) -> 2485.4952 | L38: =IFERROR(L28/22,0) -> 2522.9682 | M38: =IFERROR(M28/19,0) -> 2649 | N38: =IFERROR(N28/22,0) -> 2499.5091 | O38: =IFERROR(O28/254,0) -> 2495.1453 | Q38: =IFERROR(Q28/21,0) -> 2370.319 | R38: =IFERROR(R28/20,0) -> 2451.67 | S38: =IFERROR(S28/22,0) -> 2390.3818 | T38: =IFERROR(T28/22,0) -> 2585.5409 | U38: =IFERROR(U28/20,0) -> 2591.675 | V38: =IFERROR(V28/22,0) -> 2460.1864 | W38: =IFERROR(W28/22,0) -> 2446.6682 | X38: =IFERROR(X28/21,0) -> 2508.6333 | Y38: =IFERROR(Y28/21,0) -> 2483.3524 | Z38: =IFERROR(Z28/22,0) -> 2520.9227 | AA38: =IFERROR(AA28/19,0) -> 2646.6316 | AB38: =IFERROR(AB28/22,0) -> 2497.4636 | AC38: =IFERROR(AC28/254,0) -> 2494.4366 | AE38: =IFERROR(AE28/21,0) -> 0 | AF38: =IFERROR(AF28/20,0) -> 0 | AG38: =IFERROR(AG28/22,0) -> 0 | AH38: =IFERROR(AH28/22,0) -> 0 | AI38: =IFERROR(AI28/20,0) -> 0 | AJ38: =IFERROR(AJ28/22,0) -> 0 | AK38: =IFERROR(AK28/22,0) -> 0 | AL38: =IFERROR(AL28/21,0) -> 0 | AM38: =IFERROR(AM28/21,0) -> -2.1428571 | AN38: =IFERROR(AN28/22,0) -> -2.0454545 | AO38: =IFERROR(AO28/19,0) -> -2.3684211 | AP38: =IFERROR(AP28/22,0) -> -2.0454545 | AQ38: =IFERROR(AQ28/254,0) -> -0.70866142 | AS38: =IFERROR(AS28/21,0) -> 0 | AT38: =IFERROR(AT28/20,0) -> 0 | AU38: =IFERROR(AU28/22,0) -> 0 | AV38: =IFERROR(AV28/22,0) -> 0 | AW38: =IFERROR(AW28/20,0) -> 0 | AX38: =IFERROR(AX28/22,0) -> 0 | AY38: =IFERROR(AY28/22,0) -> 0 | AZ38: =IFERROR(AZ28/21,0) -> 0 | BA38: =IFERROR(BA28/21,0) -> 70.952381 | BB38: =IFERROR(BB28/22,0) -> -47.272727 | BC38: =IFERROR(BC28/19,0) -> -11.578947 | BD38: =IFERROR(BD28/22,0) -> 15.454545 | BE38: =IFERROR(BE28/254,0) -> 2.2440945 | BG38: =IFERROR(BG28/21,0) -> 2370.319 | BH38: =IFERROR(BH28/20,0) -> 2451.67 | BI38: =IFERROR(BI28/22,0) -> 2390.3818 | BJ38: =IFERROR(BJ28/22,0) -> 2585.5409 | BK38: =IFERROR(BK28/20,0) -> 2591.675 | BL38: =IFERROR(BL28/22,0) -> 2460.1864 | BM38: =IFERROR(BM28/22,0) -> 2446.6682 | BN38: =IFERROR(BN28/21,0) -> 2508.6333 | BO38: =IFERROR(BO28/21,0) -> 2554.3048 | BP38: =IFERROR(BP28/22,0) -> 2473.65 | BQ38: =IFERROR(BQ28/19,0) -> 2635.0526 | BR38: =IFERROR(BR28/22,0) -> 2512.9182 | BS38: =IFERROR(BS28/254,0) -> 2496.6807
B40: Net Inventory | C40: ='Alder'!C40+'Beacon'!C40+'Cobalt'!C40+'Delta'!C40+'Ember'!C40+'Falcon'!C40+'Granite'!C40+'Hollis'!C40+'SAFEREG'!C40 -> 85813.1 | D40: ='Alder'!D40+'Beacon'!D40+'Cobalt'!D40+'Delta'!D40+'Ember'!D40+'Falcon'!D40+'Granite'!D40+'Hollis'!D40+'SAFEREG'!D40 -> 85188.2 | E40: ='Alder'!E40+'Beacon'!E40+'Cobalt'!E40+'Delta'!E40+'Ember'!E40+'Falcon'!E40+'Granite'!E40+'Hollis'!E40+'SAFEREG'!E40 -> 90743.6 | F40: ='Alder'!F40+'Beacon'!F40+'Cobalt'!F40+'Delta'!F40+'Ember'!F40+'Falcon'!F40+'Granite'!F40+'Hollis'!F40+'SAFEREG'!F40 -> 98182 | G40: ='Alder'!G40+'Beacon'!G40+'Cobalt'!G40+'Delta'!G40+'Ember'!G40+'Falcon'!G40+'Granite'!G40+'Hollis'!G40+'SAFEREG'!G40 -> 87470.4 | H40: ='Alder'!H40+'Beacon'!H40+'Cobalt'!H40+'Delta'!H40+'Ember'!H40+'Falcon'!H40+'Granite'!H40+'Hollis'!H40+'SAFEREG'!H40 -> 88474.9 | I40: ='Alder'!I40+'Beacon'!I40+'Cobalt'!I40+'Delta'!I40+'Ember'!I40+'Falcon'!I40+'Granite'!I40+'Hollis'!I40+'SAFEREG'!I40 -> 86267.1 | J40: ='Alder'!J40+'Beacon'!J40+'Cobalt'!J40+'Delta'!J40+'Ember'!J40+'Falcon'!J40+'Granite'!J40+'Hollis'!J40+'SAFEREG'!J40 -> 81103.4 | ... N40: ='Alder'!N40+'Beacon'!N40+'Cobalt'!N40+'Delta'!N40+'Ember'!N40+'Falcon'!N40+'Granite'!N40+'Hollis'!N40+'SAFEREG'!N40 -> 84145.9 | O40: =N40 -> 84145.9 | Q40: ='Alder'!Q40+'Beacon'!Q40+'Cobalt'!Q40+'Delta'!Q40+'Ember'!Q40+'Falcon'!Q40+'Granite'!Q40+'Hollis'!Q40+'SAFEREG'!Q40 -> 85813.1 | R40: ='Alder'!R40+'Beacon'!R40+'Cobalt'!R40+'Delta'!R40+'Ember'!R40+'Falcon'!R40+'Granite'!R40+'Hollis'!R40+'SAFEREG'!R40 -> 85188.2 | S40: ='Alder'!S40+'Beacon'!S40+'Cobalt'!S40+'Delta'!S40+'Ember'!S40+'Falcon'!S40+'Granite'!S40+'Hollis'!S40+'SAFEREG'!S40 -> 90743.6 | T40: ='Alder'!T40+'Beacon'!T40+'Cobalt'!T40+'Delta'!T40+'Ember'!T40+'Falcon'!T40+'Granite'!T40+'Hollis'!T40+'SAFEREG'!T40 -> 98182 | U40: ='Alder'!U40+'Beacon'!U40+'Cobalt'!U40+'Delta'!U40+'Ember'!U40+'Falcon'!U40+'Granite'!U40+'Hollis'!U40+'SAFEREG'!U40 -> 87470.4 | V40: ='Alder'!V40+'Beacon'!V40+'Cobalt'!V40+'Delta'!V40+'Ember'!V40+'Falcon'!V40+'Granite'!V40+'Hollis'!V40+'SAFEREG'!V40 -> 88474.9 | W40: ='Alder'!W40+'Beacon'!W40+'Cobalt'!W40+'Delta'!W40+'Ember'!W40+'Falcon'!W40+'Granite'!W40+'Hollis'!W40+'SAFEREG'!W40 -> 86267.1 | X40: ='Alder'!X40+'Beacon'!X40+'Cobalt'!X40+'Delta'!X40+'Ember'!X40+'Falcon'!X40+'Granite'!X40+'Hollis'!X40+'SAFEREG'!X40 -> 81103.4 | ... AB40: ='Alder'!AB40+'Beacon'!AB40+'Cobalt'!AB40+'Delta'!AB40+'Ember'!AB40+'Falcon'!AB40+'Granite'!AB40+'Hollis'!AB40+'SAFEREG'!AB40 -> 84145.9 | AC40: =AB40 -> 84145.9 | AE40: =Q40-C40 -> 0 | AF40: =R40-D40 -> 0 | AG40: =S40-E40 -> 0 | AH40: =T40-F40 -> 0 | AI40: =U40-G40 -> 0 | AJ40: =V40-H40 -> 0 | AK40: =W40-I40 -> 0 | AL40: =X40-J40 -> 0 | ... AP40: =AB40-N40 -> 0 | AQ40: =AP40 -> 0 | AS40: ='Safety-Adj'!C95 -> 0 | AT40: ='Safety-Adj'!D95 -> 0 | AU40: ='Safety-Adj'!E95 -> 0 | AV40: ='Safety-Adj'!F95 -> 0 | AW40: ='Safety-Adj'!G95 -> 0 | AX40: ='Safety-Adj'!H95 -> 0 | AY40: ='Safety-Adj'!I95 -> 0 | AZ40: ='Safety-Adj'!J95 -> 0 | ... BD40: ='Safety-Adj'!N95 -> -4000 | BE40: =BD40 -> -4000 | BG40: =C40+AE40+AS40 -> 85813.1 | BH40: =D40+AF40+AT40 -> 85188.2 | BI40: =E40+AG40+AU40 -> 90743.6 | BJ40: =F40+AH40+AV40 -> 98182 | BK40: =G40+AI40+AW40 -> 87470.4 | BL40: =H40+AJ40+AX40 -> 88474.9 | BM40: =I40+AK40+AY40 -> 86267.1 | BN40: =J40+AL40+AZ40 -> 81103.4 | ... BR40: =N40+AP40+BD40 -> 80145.9 | BS40: =BR40 -> 80145.9
